2025-05-11 11:58:42.602 [INFO] [INFO] ++++++++++ Creating EntityUtils
2025-05-11 11:58:42.602 [INFO] [INFO] ++++++++++ EntityUtils custom_serializers: {}
2025-05-11 11:58:42.609 [INFO] [INFO] ++++++++++ Creating EntityUtils
2025-05-11 11:58:42.609 [INFO] [INFO] ++++++++++ EntityUtils custom_serializers: {}
2025-05-11 11:58:42.614 [INFO] [INFO] ++++++++++ Creating EntityUtils
2025-05-11 11:58:42.614 [INFO] [INFO] ++++++++++ EntityUtils custom_serializers: {}
2025-05-11 11:58:50.711 [INFO] [INFO] ++++++++++ Creating EntityUtils
2025-05-11 11:58:50.711 [INFO] [INFO] ++++++++++ EntityUtils custom_serializers: {}
2025-05-11 11:58:50.717 [INFO] [INFO] ++++++++++ Creating EntityUtils
2025-05-11 11:58:50.717 [INFO] [INFO] ++++++++++ EntityUtils custom_serializers: {}
2025-05-11 11:58:50.720 [INFO] [INFO] ++++++++++ Creating EntityUtils
2025-05-11 11:58:50.720 [INFO] [INFO] ++++++++++ EntityUtils custom_serializers: {}
2025-05-11 11:59:17.222 [INFO] [INFO] ++++++++++ Creating EntityUtils
2025-05-11 11:59:17.222 [INFO] [INFO] ++++++++++ EntityUtils custom_serializers: {}
2025-05-11 11:59:17.230 [INFO] [INFO] ++++++++++ Creating EntityUtils
2025-05-11 11:59:17.230 [INFO] [INFO] ++++++++++ EntityUtils custom_serializers: {}
2025-05-11 11:59:17.234 [INFO] [INFO] ++++++++++ Creating EntityUtils
2025-05-11 11:59:17.234 [INFO] [INFO] ++++++++++ EntityUtils custom_serializers: {}
2025-05-11 12:01:41.931 [INFO] [INFO] ++++++++++ Creating EntityUtils
2025-05-11 12:01:41.931 [INFO] [INFO] ++++++++++ EntityUtils custom_serializers: {}
2025-05-11 12:01:41.939 [INFO] [INFO] ++++++++++ Creating EntityUtils
2025-05-11 12:01:41.940 [INFO] [INFO] ++++++++++ EntityUtils custom_serializers: {}
2025-05-11 12:01:41.943 [INFO] [INFO] ++++++++++ Creating EntityUtils
2025-05-11 12:01:41.943 [INFO] [INFO] ++++++++++ EntityUtils custom_serializers: {}
2025-05-11 12:01:59.474 [INFO] [INFO] ++++++++++ Creating EntityUtils
2025-05-11 12:01:59.474 [INFO] [INFO] ++++++++++ EntityUtils custom_serializers: {}
2025-05-11 12:01:59.482 [INFO] [INFO] ++++++++++ Creating EntityUtils
2025-05-11 12:01:59.482 [INFO] [INFO] ++++++++++ EntityUtils custom_serializers: {}
2025-05-11 12:01:59.485 [INFO] [INFO] ++++++++++ Creating EntityUtils
2025-05-11 12:01:59.485 [INFO] [INFO] ++++++++++ EntityUtils custom_serializers: {}
2025-05-11 12:03:13.247 [INFO] [INFO] ++++++++++ Creating EntityUtils
2025-05-11 12:03:13.247 [INFO] [INFO] ++++++++++ EntityUtils custom_serializers: {}
2025-05-11 12:03:13.257 [INFO] [INFO] ++++++++++ Creating EntityUtils
2025-05-11 12:03:13.257 [INFO] [INFO] ++++++++++ EntityUtils custom_serializers: {}
2025-05-11 12:03:13.262 [INFO] [INFO] ++++++++++ Creating EntityUtils
2025-05-11 12:03:13.262 [INFO] [INFO] ++++++++++ EntityUtils custom_serializers: {}
2025-05-11 12:03:24.488 [INFO] [INFO] Setting up test environment...
2025-05-11 12:03:24.489 [INFO] [INFO] Removing .\.pytest_cache
2025-05-11 12:03:24.536 [INFO] [INFO] Test files in this session: {'c:\\Users\\Phil\\Desktop\\Projects\\shared-libs\\python\\errors\\tests\\test_error.py'}
2025-05-11 12:03:24.537 [INFO] [INFO] No Docker Compose files found for any test files. Continuing without Docker setup.
2025-05-11 12:03:24.561 [ERROR] [ERROR] Error in Database.connect: Connection refused
2025-05-11 12:03:24.566 [INFO] [INFO] App caught error: Error:
{
    "description": null,
    "action": null,
    "critical": false,
    "location": "c:\\Users\\Phil\\Desktop\\Projects\\shared-libs\\python\\errors\\try_catch.py wrapper line 41",
    "error": {
        "description": "Connection refused",
        "location": "c:\\Users\\Phil\\Desktop\\Projects\\shared-libs\\python\\errors\\tests\\test_error.py connect line 62"
    }
}
Trace:
['c:\\Users\\Phil\\Desktop\\Projects\\shared-libs\\python\\errors\\try_catch.py wrapper line 41', 'c:\\Users\\Phil\\Desktop\\Projects\\shared-libs\\python\\errors\\tests\\test_error.py connect line 62']
2025-05-11 12:03:24.566 [INFO] [INFO] There was an error at the App level: division by zero
2025-05-11 12:03:24.567 [INFO] [INFO] Tearing down test environment...
2025-05-11 12:03:25.404 [INFO] [INFO] ++++++++++ Creating EntityUtils
2025-05-11 12:03:25.404 [INFO] [INFO] ++++++++++ EntityUtils custom_serializers: {}
2025-05-11 12:03:25.411 [INFO] [INFO] ++++++++++ Creating EntityUtils
2025-05-11 12:03:25.412 [INFO] [INFO] ++++++++++ EntityUtils custom_serializers: {}
2025-05-11 12:03:25.416 [INFO] [INFO] ++++++++++ Creating EntityUtils
2025-05-11 12:03:25.416 [INFO] [INFO] ++++++++++ EntityUtils custom_serializers: {}
2025-05-11 12:06:01.804 [INFO] [INFO] ++++++++++ Creating EntityUtils
2025-05-11 12:06:01.804 [INFO] [INFO] ++++++++++ EntityUtils custom_serializers: {}
2025-05-11 12:06:01.812 [INFO] [INFO] ++++++++++ Creating EntityUtils
2025-05-11 12:06:01.812 [INFO] [INFO] ++++++++++ EntityUtils custom_serializers: {}
2025-05-11 12:06:01.816 [INFO] [INFO] ++++++++++ Creating EntityUtils
2025-05-11 12:06:01.816 [INFO] [INFO] ++++++++++ EntityUtils custom_serializers: {}
2025-05-11 12:06:08.601 [INFO] [INFO] Setting up test environment...
2025-05-11 12:06:08.601 [INFO] [INFO] Removing .\.pytest_cache
2025-05-11 12:06:08.631 [INFO] [INFO] Test files in this session: {'c:\\Users\\Phil\\Desktop\\Projects\\shared-libs\\python\\errors\\tests\\test_error.py'}
2025-05-11 12:06:08.632 [INFO] [INFO] No Docker Compose files found for any test files. Continuing without Docker setup.
2025-05-11 12:06:08.636 [INFO] [INFO] App caught error: Error:
{
    "description": null,
    "action": null,
    "critical": false,
    "location": "c:\\Users\\Phil\\Desktop\\Projects\\shared-libs\\python\\errors\\try_catch.py wrapper line 40",
    "error": {
        "description": "Connection refused",
        "location": "c:\\Users\\Phil\\Desktop\\Projects\\shared-libs\\python\\errors\\tests\\test_error.py connect line 62"
    }
}
Trace:
['c:\\Users\\Phil\\Desktop\\Projects\\shared-libs\\python\\errors\\try_catch.py wrapper line 40', 'c:\\Users\\Phil\\Desktop\\Projects\\shared-libs\\python\\errors\\tests\\test_error.py connect line 62']
2025-05-11 12:06:08.637 [INFO] [INFO] Database.query (('SELECT * FROM users',)) returned Results for: SELECT * FROM users
2025-05-11 12:06:08.637 [INFO] [INFO] There was an error at the App level: division by zero
2025-05-11 12:06:08.638 [INFO] [INFO] Tearing down test environment...
2025-05-11 12:07:46.820 [INFO] [INFO] ++++++++++ Creating EntityUtils
2025-05-11 12:07:46.820 [INFO] [INFO] ++++++++++ EntityUtils custom_serializers: {}
2025-05-11 12:07:46.829 [INFO] [INFO] ++++++++++ Creating EntityUtils
2025-05-11 12:07:46.830 [INFO] [INFO] ++++++++++ EntityUtils custom_serializers: {}
2025-05-11 12:07:46.835 [INFO] [INFO] ++++++++++ Creating EntityUtils
2025-05-11 12:07:46.835 [INFO] [INFO] ++++++++++ EntityUtils custom_serializers: {}
2025-05-11 12:07:50.072 [INFO] [INFO] Setting up test environment...
2025-05-11 12:07:50.072 [INFO] [INFO] Removing .\.pytest_cache
2025-05-11 12:07:50.108 [INFO] [INFO] Test files in this session: {'c:\\Users\\Phil\\Desktop\\Projects\\shared-libs\\python\\errors\\tests\\test_error.py'}
2025-05-11 12:07:50.108 [INFO] [INFO] No Docker Compose files found for any test files. Continuing without Docker setup.
2025-05-11 12:07:50.111 [ERROR] [ERROR] App caught error: Error:
{
    "description": null,
    "action": null,
    "critical": false,
    "location": "c:\\Users\\Phil\\Desktop\\Projects\\shared-libs\\python\\errors\\try_catch.py wrapper line 40",
    "error": {
        "description": "Connection refused",
        "location": "c:\\Users\\Phil\\Desktop\\Projects\\shared-libs\\python\\errors\\tests\\test_error.py connect line 62"
    }
}
Trace:
['c:\\Users\\Phil\\Desktop\\Projects\\shared-libs\\python\\errors\\try_catch.py wrapper line 40', 'c:\\Users\\Phil\\Desktop\\Projects\\shared-libs\\python\\errors\\tests\\test_error.py connect line 62']
2025-05-11 12:07:50.111 [INFO] [INFO] Database.query (('SELECT * FROM users',)) returned Results for: SELECT * FROM users
2025-05-11 12:07:50.111 [ERROR] [ERROR] There was an error at the App level: division by zero
2025-05-11 12:07:50.112 [INFO] [INFO] Tearing down test environment...
2025-05-11 12:11:18.138 [INFO] [INFO] ++++++++++ Creating EntityUtils
2025-05-11 12:11:18.139 [INFO] [INFO] ++++++++++ EntityUtils custom_serializers: {}
2025-05-11 12:11:18.149 [INFO] [INFO] ++++++++++ Creating EntityUtils
2025-05-11 12:11:18.149 [INFO] [INFO] ++++++++++ EntityUtils custom_serializers: {}
2025-05-11 12:11:18.152 [INFO] [INFO] ++++++++++ Creating EntityUtils
2025-05-11 12:11:18.153 [INFO] [INFO] ++++++++++ EntityUtils custom_serializers: {}
2025-05-11 12:12:20.978 [INFO] [INFO] ++++++++++ Creating EntityUtils
2025-05-11 12:12:20.978 [INFO] [INFO] ++++++++++ EntityUtils custom_serializers: {}
2025-05-11 12:12:20.989 [INFO] [INFO] ++++++++++ Creating EntityUtils
2025-05-11 12:12:20.989 [INFO] [INFO] ++++++++++ EntityUtils custom_serializers: {}
2025-05-11 12:12:20.994 [INFO] [INFO] ++++++++++ Creating EntityUtils
2025-05-11 12:12:20.994 [INFO] [INFO] ++++++++++ EntityUtils custom_serializers: {}
2025-05-11 12:12:28.523 [INFO] [INFO] Setting up test environment...
2025-05-11 12:12:28.524 [INFO] [INFO] Removing .\.pytest_cache
2025-05-11 12:12:28.555 [INFO] [INFO] Test files in this session: {'c:\\Users\\Phil\\Desktop\\Projects\\shared-libs\\python\\errors\\tests\\test_error.py'}
2025-05-11 12:12:28.555 [INFO] [INFO] No Docker Compose files found for any test files. Continuing without Docker setup.
2025-05-11 12:12:28.557 [ERROR] [ERROR] Error in Database.connect: ValueError: Connection refused
2025-05-11 12:12:28.560 [ERROR] [ERROR] App caught error: Error:
{
    "description": "Failed in Database.connect",
    "action": null,
    "critical": false,
    "location": "c:\\Users\\Phil\\Desktop\\Projects\\shared-libs\\python\\errors\\try_catch.py wrapper line 64",
    "error": {
        "description": "Connection refused",
        "location": "c:\\Users\\Phil\\Desktop\\Projects\\shared-libs\\python\\errors\\tests\\test_error.py connect line 62"
    }
}
Trace:
['c:\\Users\\Phil\\Desktop\\Projects\\shared-libs\\python\\errors\\try_catch.py wrapper line 64', 'c:\\Users\\Phil\\Desktop\\Projects\\shared-libs\\python\\errors\\tests\\test_error.py connect line 62']
2025-05-11 12:12:28.560 [INFO] [INFO] There was an error at the App level: division by zero
2025-05-11 12:12:28.561 [INFO] [INFO] Tearing down test environment...
2025-05-11 12:18:54.734 [INFO] [INFO] ++++++++++ Creating EntityUtils
2025-05-11 12:18:54.734 [INFO] [INFO] ++++++++++ EntityUtils custom_serializers: {}
2025-05-11 12:18:54.742 [INFO] [INFO] ++++++++++ Creating EntityUtils
2025-05-11 12:18:54.742 [INFO] [INFO] ++++++++++ EntityUtils custom_serializers: {}
2025-05-11 12:18:54.745 [INFO] [INFO] ++++++++++ Creating EntityUtils
2025-05-11 12:18:54.745 [INFO] [INFO] ++++++++++ EntityUtils custom_serializers: {}
2025-05-11 12:18:57.413 [INFO] [INFO] Setting up test environment...
2025-05-11 12:18:57.414 [INFO] [INFO] Removing .\.pytest_cache
2025-05-11 12:18:57.446 [INFO] [INFO] Test files in this session: {'c:\\Users\\Phil\\Desktop\\Projects\\shared-libs\\python\\errors\\tests\\test_error.py'}
2025-05-11 12:18:57.447 [INFO] [INFO] No Docker Compose files found for any test files. Continuing without Docker setup.
2025-05-11 12:18:57.450 [ERROR] [ERROR] App caught error: Error:
{
    "description": "An error happened in Database.connect: Connection refused",
    "action": null,
    "critical": false,
    "location": "c:\\Users\\Phil\\Desktop\\Projects\\shared-libs\\python\\errors\\tests\\test_error.py connect line 62",
    "error": {
        "description": "Connection refused",
        "location": "c:\\Users\\Phil\\Desktop\\Projects\\shared-libs\\python\\errors\\tests\\test_error.py connect line 62"
    }
}
Trace:
['c:\\Users\\Phil\\Desktop\\Projects\\shared-libs\\python\\errors\\tests\\test_error.py connect line 62', 'c:\\Users\\Phil\\Desktop\\Projects\\shared-libs\\python\\errors\\tests\\test_error.py connect line 62']
2025-05-11 12:18:57.451 [INFO] [INFO] There was an error at the App level: division by zero
2025-05-11 12:18:57.452 [INFO] [INFO] Tearing down test environment...
2025-05-11 12:19:43.239 [INFO] [INFO] ++++++++++ Creating EntityUtils
2025-05-11 12:19:43.239 [INFO] [INFO] ++++++++++ EntityUtils custom_serializers: {}
2025-05-11 12:19:43.250 [INFO] [INFO] ++++++++++ Creating EntityUtils
2025-05-11 12:19:43.250 [INFO] [INFO] ++++++++++ EntityUtils custom_serializers: {}
2025-05-11 12:19:43.254 [INFO] [INFO] ++++++++++ Creating EntityUtils
2025-05-11 12:19:43.254 [INFO] [INFO] ++++++++++ EntityUtils custom_serializers: {}
2025-05-11 12:19:47.301 [INFO] [INFO] ++++++++++ Creating EntityUtils
2025-05-11 12:19:47.301 [INFO] [INFO] ++++++++++ EntityUtils custom_serializers: {}
2025-05-11 12:19:47.315 [INFO] [INFO] ++++++++++ Creating EntityUtils
2025-05-11 12:19:47.315 [INFO] [INFO] ++++++++++ EntityUtils custom_serializers: {}
2025-05-11 12:19:47.320 [INFO] [INFO] ++++++++++ Creating EntityUtils
2025-05-11 12:19:47.320 [INFO] [INFO] ++++++++++ EntityUtils custom_serializers: {}
2025-05-11 12:19:54.064 [INFO] [INFO] Setting up test environment...
2025-05-11 12:19:54.065 [INFO] [INFO] Removing .\.pytest_cache
2025-05-11 12:19:54.098 [INFO] [INFO] Test files in this session: {'c:\\Users\\Phil\\Desktop\\Projects\\shared-libs\\python\\errors\\tests\\test_error.py'}
2025-05-11 12:19:54.099 [INFO] [INFO] No Docker Compose files found for any test files. Continuing without Docker setup.
2025-05-11 12:19:54.101 [ERROR] [ERROR] App caught error: Error:
{
    "description": "An error happened in Database.connect: division by zero",
    "action": null,
    "critical": false,
    "location": "c:\\Users\\Phil\\Desktop\\Projects\\shared-libs\\python\\errors\\tests\\test_error.py connect line 62",
    "error": {
        "description": "division by zero",
        "location": "c:\\Users\\Phil\\Desktop\\Projects\\shared-libs\\python\\errors\\tests\\test_error.py connect line 62"
    }
}
Trace:
['c:\\Users\\Phil\\Desktop\\Projects\\shared-libs\\python\\errors\\tests\\test_error.py connect line 62', 'c:\\Users\\Phil\\Desktop\\Projects\\shared-libs\\python\\errors\\tests\\test_error.py connect line 62']
2025-05-11 12:19:54.101 [INFO] [INFO] There was an error at the App level: division by zero
2025-05-11 12:19:54.102 [INFO] [INFO] Tearing down test environment...
2025-05-11 12:20:34.666 [INFO] [INFO] ++++++++++ Creating EntityUtils
2025-05-11 12:20:34.666 [INFO] [INFO] ++++++++++ EntityUtils custom_serializers: {}
2025-05-11 12:20:34.675 [INFO] [INFO] ++++++++++ Creating EntityUtils
2025-05-11 12:20:34.675 [INFO] [INFO] ++++++++++ EntityUtils custom_serializers: {}
2025-05-11 12:20:34.678 [INFO] [INFO] ++++++++++ Creating EntityUtils
2025-05-11 12:20:34.678 [INFO] [INFO] ++++++++++ EntityUtils custom_serializers: {}
2025-05-11 12:20:37.316 [INFO] [INFO] Setting up test environment...
2025-05-11 12:20:37.317 [INFO] [INFO] Removing .\.pytest_cache
2025-05-11 12:20:37.347 [INFO] [INFO] Test files in this session: {'c:\\Users\\Phil\\Desktop\\Projects\\shared-libs\\python\\errors\\tests\\test_error.py'}
2025-05-11 12:20:37.348 [INFO] [INFO] No Docker Compose files found for any test files. Continuing without Docker setup.
2025-05-11 12:20:37.350 [ERROR] [ERROR] App caught error: Error:
{
    "description": "An error happened in Database.connect: Connection refused",
    "action": null,
    "critical": false,
    "location": "c:\\Users\\Phil\\Desktop\\Projects\\shared-libs\\python\\errors\\tests\\test_error.py connect line 63",
    "error": {
        "description": "Connection refused",
        "location": "c:\\Users\\Phil\\Desktop\\Projects\\shared-libs\\python\\errors\\tests\\test_error.py connect line 63"
    }
}
Trace:
['c:\\Users\\Phil\\Desktop\\Projects\\shared-libs\\python\\errors\\tests\\test_error.py connect line 63', 'c:\\Users\\Phil\\Desktop\\Projects\\shared-libs\\python\\errors\\tests\\test_error.py connect line 63']
2025-05-11 12:20:37.350 [INFO] [INFO] There was an error at the App level: division by zero
2025-05-11 12:20:37.351 [INFO] [INFO] Tearing down test environment...
2025-05-11 12:21:21.828 [INFO] [INFO] ++++++++++ Creating EntityUtils
2025-05-11 12:21:21.828 [INFO] [INFO] ++++++++++ EntityUtils custom_serializers: {}
2025-05-11 12:21:21.837 [INFO] [INFO] ++++++++++ Creating EntityUtils
2025-05-11 12:21:21.837 [INFO] [INFO] ++++++++++ EntityUtils custom_serializers: {}
2025-05-11 12:21:21.841 [INFO] [INFO] ++++++++++ Creating EntityUtils
2025-05-11 12:21:21.841 [INFO] [INFO] ++++++++++ EntityUtils custom_serializers: {}
2025-05-11 12:21:29.871 [INFO] [INFO] Setting up test environment...
2025-05-11 12:21:29.871 [INFO] [INFO] Removing .\.pytest_cache
2025-05-11 12:21:29.902 [INFO] [INFO] Test files in this session: {'c:\\Users\\Phil\\Desktop\\Projects\\shared-libs\\python\\errors\\tests\\test_error.py'}
2025-05-11 12:21:29.903 [INFO] [INFO] No Docker Compose files found for any test files. Continuing without Docker setup.
2025-05-11 12:21:29.906 [ERROR] [ERROR] App caught error: Error:
{
    "description": "An error happened in Database.connect: Connection refused",
    "action": null,
    "critical": false,
    "location": "c:\\Users\\Phil\\Desktop\\Projects\\shared-libs\\python\\errors\\tests\\test_error.py connect line 63",
    "error": {
        "description": "Connection refused",
        "location": "c:\\Users\\Phil\\Desktop\\Projects\\shared-libs\\python\\errors\\tests\\test_error.py connect line 63"
    }
}
Trace:
['c:\\Users\\Phil\\Desktop\\Projects\\shared-libs\\python\\errors\\tests\\test_error.py connect line 63', 'c:\\Users\\Phil\\Desktop\\Projects\\shared-libs\\python\\errors\\tests\\test_error.py connect line 63']
2025-05-11 12:21:29.906 [INFO] [INFO] There was an error at the App level: division by zero
2025-05-11 12:21:29.907 [INFO] [INFO] Tearing down test environment...
2025-05-11 12:22:01.027 [INFO] [INFO] ++++++++++ Creating EntityUtils
2025-05-11 12:22:01.028 [INFO] [INFO] ++++++++++ EntityUtils custom_serializers: {}
2025-05-11 12:22:01.038 [INFO] [INFO] ++++++++++ Creating EntityUtils
2025-05-11 12:22:01.038 [INFO] [INFO] ++++++++++ EntityUtils custom_serializers: {}
2025-05-11 12:22:01.041 [INFO] [INFO] ++++++++++ Creating EntityUtils
2025-05-11 12:22:01.042 [INFO] [INFO] ++++++++++ EntityUtils custom_serializers: {}
2025-05-11 12:22:04.023 [INFO] [INFO] Setting up test environment...
2025-05-11 12:22:04.023 [INFO] [INFO] Removing .\.pytest_cache
2025-05-11 12:22:04.054 [INFO] [INFO] Test files in this session: {'c:\\Users\\Phil\\Desktop\\Projects\\shared-libs\\python\\errors\\tests\\test_error.py'}
2025-05-11 12:22:04.055 [INFO] [INFO] No Docker Compose files found for any test files. Continuing without Docker setup.
2025-05-11 12:22:04.057 [ERROR] [ERROR] App caught error: Error:
{
    "description": "An error happened in Database.connect: Connection refused",
    "action": null,
    "critical": false,
    "location": "c:\\Users\\Phil\\Desktop\\Projects\\shared-libs\\python\\errors\\tests\\test_error.py connect line 63",
    "error": {
        "description": "Connection refused",
        "location": "c:\\Users\\Phil\\Desktop\\Projects\\shared-libs\\python\\errors\\tests\\test_error.py connect line 63"
    }
}
Trace:
['c:\\Users\\Phil\\Desktop\\Projects\\shared-libs\\python\\errors\\tests\\test_error.py connect line 63', 'c:\\Users\\Phil\\Desktop\\Projects\\shared-libs\\python\\errors\\tests\\test_error.py connect line 63']
2025-05-11 12:22:04.057 [INFO] [INFO] There was an error at the App level: division by zero
2025-05-11 12:22:04.058 [INFO] [INFO] Tearing down test environment...
2025-05-11 12:23:50.585 [INFO] [INFO] ++++++++++ Creating EntityUtils
2025-05-11 12:23:50.585 [INFO] [INFO] ++++++++++ EntityUtils custom_serializers: {}
2025-05-11 12:23:50.592 [INFO] [INFO] ++++++++++ Creating EntityUtils
2025-05-11 12:23:50.592 [INFO] [INFO] ++++++++++ EntityUtils custom_serializers: {}
2025-05-11 12:23:50.596 [INFO] [INFO] ++++++++++ Creating EntityUtils
2025-05-11 12:23:50.596 [INFO] [INFO] ++++++++++ EntityUtils custom_serializers: {}
2025-05-11 12:23:56.362 [INFO] [INFO] Setting up test environment...
2025-05-11 12:23:56.362 [INFO] [INFO] Removing .\.pytest_cache
2025-05-11 12:23:56.403 [INFO] [INFO] Test files in this session: {'c:\\Users\\Phil\\Desktop\\Projects\\shared-libs\\python\\errors\\tests\\test_error.py'}
2025-05-11 12:23:56.404 [INFO] [INFO] No Docker Compose files found for any test files. Continuing without Docker setup.
2025-05-11 12:23:56.406 [ERROR] [ERROR] App caught error: Error:
{
    "description": "An error happened in Database.connect: Connection refused",
    "action": null,
    "critical": false,
    "location": "c:\\Users\\Phil\\Desktop\\Projects\\shared-libs\\python\\errors\\tests\\test_error.py connect line 63",
    "error": {
        "description": "Connection refused",
        "location": "c:\\Users\\Phil\\Desktop\\Projects\\shared-libs\\python\\errors\\tests\\test_error.py connect line 63"
    }
}
Trace:
['c:\\Users\\Phil\\Desktop\\Projects\\shared-libs\\python\\errors\\tests\\test_error.py connect line 63', 'c:\\Users\\Phil\\Desktop\\Projects\\shared-libs\\python\\errors\\tests\\test_error.py connect line 63']
2025-05-11 12:23:56.406 [INFO] [INFO] There was an error at the App level: division by zero
2025-05-11 12:23:56.407 [INFO] [INFO] Tearing down test environment...
2025-05-11 12:24:12.659 [INFO] [INFO] ++++++++++ Creating EntityUtils
2025-05-11 12:24:12.659 [INFO] [INFO] ++++++++++ EntityUtils custom_serializers: {}
2025-05-11 12:24:12.669 [INFO] [INFO] ++++++++++ Creating EntityUtils
2025-05-11 12:24:12.670 [INFO] [INFO] ++++++++++ EntityUtils custom_serializers: {}
2025-05-11 12:24:12.674 [INFO] [INFO] ++++++++++ Creating EntityUtils
2025-05-11 12:24:12.674 [INFO] [INFO] ++++++++++ EntityUtils custom_serializers: {}
2025-05-11 12:24:14.928 [INFO] [INFO] Setting up test environment...
2025-05-11 12:24:14.928 [INFO] [INFO] Removing .\.pytest_cache
2025-05-11 12:24:14.962 [INFO] [INFO] Test files in this session: {'c:\\Users\\Phil\\Desktop\\Projects\\shared-libs\\python\\errors\\tests\\test_error.py'}
2025-05-11 12:24:14.963 [INFO] [INFO] No Docker Compose files found for any test files. Continuing without Docker setup.
2025-05-11 12:24:14.967 [ERROR] [ERROR] App caught error: An error happened in Database.connect: Connection refused
Error:
{
    "description": "An error happened in Database.connect: Connection refused",
    "action": null,
    "critical": false,
    "location": "c:\\Users\\Phil\\Desktop\\Projects\\shared-libs\\python\\errors\\tests\\test_error.py connect line 63",
    "error": {
        "description": "Connection refused",
        "location": "c:\\Users\\Phil\\Desktop\\Projects\\shared-libs\\python\\errors\\tests\\test_error.py connect line 63"
    }
}
Trace:
['c:\\Users\\Phil\\Desktop\\Projects\\shared-libs\\python\\errors\\tests\\test_error.py connect line 63', 'c:\\Users\\Phil\\Desktop\\Projects\\shared-libs\\python\\errors\\tests\\test_error.py connect line 63']
2025-05-11 12:24:14.967 [INFO] [INFO] There was an error at the App level: division by zero
2025-05-11 12:24:14.968 [INFO] [INFO] Tearing down test environment...
2025-05-11 12:24:51.695 [INFO] [INFO] ++++++++++ Creating EntityUtils
2025-05-11 12:24:51.695 [INFO] [INFO] ++++++++++ EntityUtils custom_serializers: {}
2025-05-11 12:24:51.705 [INFO] [INFO] ++++++++++ Creating EntityUtils
2025-05-11 12:24:51.705 [INFO] [INFO] ++++++++++ EntityUtils custom_serializers: {}
2025-05-11 12:24:51.708 [INFO] [INFO] ++++++++++ Creating EntityUtils
2025-05-11 12:24:51.708 [INFO] [INFO] ++++++++++ EntityUtils custom_serializers: {}
2025-05-11 12:28:05.986 [INFO] [INFO] ++++++++++ Creating EntityUtils
2025-05-11 12:28:05.986 [INFO] [INFO] ++++++++++ EntityUtils custom_serializers: {}
2025-05-11 12:28:05.995 [INFO] [INFO] ++++++++++ Creating EntityUtils
2025-05-11 12:28:05.995 [INFO] [INFO] ++++++++++ EntityUtils custom_serializers: {}
2025-05-11 12:28:05.999 [INFO] [INFO] ++++++++++ Creating EntityUtils
2025-05-11 12:28:05.999 [INFO] [INFO] ++++++++++ EntityUtils custom_serializers: {}
2025-05-11 12:28:08.757 [INFO] [INFO] Setting up test environment...
2025-05-11 12:28:08.759 [INFO] [INFO] Removing .\.pytest_cache
2025-05-11 12:28:08.789 [INFO] [INFO] Test files in this session: {'c:\\Users\\Phil\\Desktop\\Projects\\shared-libs\\python\\errors\\tests\\test_error.py'}
2025-05-11 12:28:08.790 [INFO] [INFO] No Docker Compose files found for any test files. Continuing without Docker setup.
2025-05-11 12:28:08.792 [ERROR] [ERROR] App caught error: An error happened in Database.connect: Connection refused (line 63 in c:\Users\Phil\Desktop\Projects\shared-libs\python\errors\tests\test_error.py)
Error:
{
    "description": "An error happened in Database.connect: Connection refused (line 63 in c:\\Users\\Phil\\Desktop\\Projects\\shared-libs\\python\\errors\\tests\\test_error.py)",
    "action": null,
    "critical": false,
    "location": "c:\\Users\\Phil\\Desktop\\Projects\\shared-libs\\python\\errors\\tests\\test_error.py connect line 63",
    "error": {
        "description": "Connection refused",
        "location": "c:\\Users\\Phil\\Desktop\\Projects\\shared-libs\\python\\errors\\tests\\test_error.py connect line 63"
    }
}
Trace:
['c:\\Users\\Phil\\Desktop\\Projects\\shared-libs\\python\\errors\\tests\\test_error.py connect line 63', 'c:\\Users\\Phil\\Desktop\\Projects\\shared-libs\\python\\errors\\tests\\test_error.py connect line 63']
2025-05-11 12:28:08.792 [INFO] [INFO] There was an error at the App level: division by zero
2025-05-11 12:28:08.793 [INFO] [INFO] Tearing down test environment...
2025-05-11 12:31:37.360 [INFO] [INFO] ++++++++++ Creating EntityUtils
2025-05-11 12:31:37.360 [INFO] [INFO] ++++++++++ EntityUtils custom_serializers: {}
2025-05-11 12:31:37.367 [INFO] [INFO] ++++++++++ Creating EntityUtils
2025-05-11 12:31:37.367 [INFO] [INFO] ++++++++++ EntityUtils custom_serializers: {}
2025-05-11 12:31:37.372 [INFO] [INFO] ++++++++++ Creating EntityUtils
2025-05-11 12:31:37.372 [INFO] [INFO] ++++++++++ EntityUtils custom_serializers: {}
2025-05-11 12:31:39.657 [INFO] [INFO] Setting up test environment...
2025-05-11 12:31:39.657 [INFO] [INFO] Removing .\.pytest_cache
2025-05-11 12:31:39.691 [INFO] [INFO] Test files in this session: {'c:\\Users\\Phil\\Desktop\\Projects\\shared-libs\\python\\errors\\tests\\test_error.py'}
2025-05-11 12:31:39.694 [INFO] [INFO] No Docker Compose files found for any test files. Continuing without Docker setup.
2025-05-11 12:31:39.697 [ERROR] [ERROR] App caught error: An error happened in Database.connect: Connection refused (line 63 in c:\Users\Phil\Desktop\Projects\shared-libs\python\errors\tests\test_error.py)
Error:
{
    "description": "An error happened in Database.connect: Connection refused (line 63 in c:\\Users\\Phil\\Desktop\\Projects\\shared-libs\\python\\errors\\tests\\test_error.py)",
    "action": null,
    "critical": false,
    "location": "c:\\Users\\Phil\\Desktop\\Projects\\shared-libs\\python\\errors\\tests\\test_error.py connect line 63",
    "error": {
        "description": "Connection refused",
        "location": "c:\\Users\\Phil\\Desktop\\Projects\\shared-libs\\python\\errors\\tests\\test_error.py connect line 63"
    }
}
Trace:
['c:\\Users\\Phil\\Desktop\\Projects\\shared-libs\\python\\errors\\tests\\test_error.py connect line 63', 'c:\\Users\\Phil\\Desktop\\Projects\\shared-libs\\python\\errors\\tests\\test_error.py connect line 63']
2025-05-11 12:31:39.698 [INFO] [INFO] There was an error at the App level: division by zero
2025-05-11 12:31:39.699 [INFO] [INFO] Tearing down test environment...
2025-05-11 12:31:48.653 [INFO] [INFO] ++++++++++ Creating EntityUtils
2025-05-11 12:31:48.653 [INFO] [INFO] ++++++++++ EntityUtils custom_serializers: {}
2025-05-11 12:31:48.663 [INFO] [INFO] ++++++++++ Creating EntityUtils
2025-05-11 12:31:48.663 [INFO] [INFO] ++++++++++ EntityUtils custom_serializers: {}
2025-05-11 12:31:48.666 [INFO] [INFO] ++++++++++ Creating EntityUtils
2025-05-11 12:31:48.666 [INFO] [INFO] ++++++++++ EntityUtils custom_serializers: {}
2025-05-11 12:31:51.648 [INFO] [INFO] Setting up test environment...
2025-05-11 12:31:51.648 [INFO] [INFO] Removing .\.pytest_cache
2025-05-11 12:31:51.677 [INFO] [INFO] Test files in this session: {'c:\\Users\\Phil\\Desktop\\Projects\\shared-libs\\python\\errors\\tests\\test_error.py'}
2025-05-11 12:31:51.678 [INFO] [INFO] No Docker Compose files found for any test files. Continuing without Docker setup.
2025-05-11 12:31:51.680 [ERROR] [ERROR] App caught: An error happened in Database.connect: Connection refused (line 63 in c:\Users\Phil\Desktop\Projects\shared-libs\python\errors\tests\test_error.py)
c:\Users\Phil\Desktop\Projects\shared-libs\python\errors\tests\test_error.py connect line 63
c:\Users\Phil\Desktop\Projects\shared-libs\python\errors\tests\test_error.py connect line 63
2025-05-11 12:31:51.681 [INFO] [INFO] There was an error at the App level: division by zero
2025-05-11 12:31:51.684 [INFO] [INFO] Tearing down test environment...
2025-05-11 12:40:04.438 [INFO] [INFO] Setting up test environment...
2025-05-11 12:40:04.438 [INFO] [INFO] Removing .\.pytest_cache
2025-05-11 12:40:04.472 [INFO] [INFO] Test files in this session: {'c:\\Users\\Phil\\Desktop\\Projects\\shared-libs\\python\\errors\\tests\\test_error.py'}
2025-05-11 12:40:04.473 [INFO] [INFO] No Docker Compose files found for any test files. Continuing without Docker setup.
2025-05-11 12:40:04.475 [ERROR] [ERROR] App caught: An error happened in Database.connect: Connection refused (line 63 in c:\Users\Phil\Desktop\Projects\shared-libs\python\errors\tests\test_error.py)
c:\Users\Phil\Desktop\Projects\shared-libs\python\errors\tests\test_error.py connect line 63
c:\Users\Phil\Desktop\Projects\shared-libs\python\errors\tests\test_error.py connect line 63
2025-05-11 12:40:04.475 [INFO] [INFO] There was an error at the App level: division by zero
2025-05-11 12:40:04.476 [INFO] [INFO] Tearing down test environment...
2025-05-11 12:40:45.601 [INFO] [INFO] ++++++++++ Creating EntityUtils
2025-05-11 12:40:45.601 [INFO] [INFO] ++++++++++ EntityUtils custom_serializers: {}
2025-05-11 12:40:45.613 [INFO] [INFO] ++++++++++ Creating EntityUtils
2025-05-11 12:40:45.613 [INFO] [INFO] ++++++++++ EntityUtils custom_serializers: {}
2025-05-11 12:40:45.619 [INFO] [INFO] ++++++++++ Creating EntityUtils
2025-05-11 12:40:45.619 [INFO] [INFO] ++++++++++ EntityUtils custom_serializers: {}
2025-05-11 12:40:47.247 [INFO] [INFO] Setting up test environment...
2025-05-11 12:40:47.247 [INFO] [INFO] Removing .\.pytest_cache
2025-05-11 12:40:47.293 [INFO] [INFO] Test files in this session: {'c:\\Users\\Phil\\Desktop\\Projects\\shared-libs\\python\\errors\\tests\\test_error.py'}
2025-05-11 12:40:47.296 [INFO] [INFO] No Docker Compose files found for any test files. Continuing without Docker setup.
2025-05-11 12:40:47.300 [ERROR] [ERROR] App caught: An error happened in Database.connect: Connection refused (line 63)
c:\Users\Phil\Desktop\Projects\shared-libs\python\errors\tests\test_error.py connect line 63
c:\Users\Phil\Desktop\Projects\shared-libs\python\errors\tests\test_error.py connect line 63
2025-05-11 12:40:47.300 [INFO] [INFO] There was an error at the App level: division by zero
2025-05-11 12:40:47.302 [INFO] [INFO] Tearing down test environment...
2025-05-11 12:41:58.783 [INFO] [INFO] ++++++++++ Creating EntityUtils
2025-05-11 12:41:58.783 [INFO] [INFO] ++++++++++ EntityUtils custom_serializers: {}
2025-05-11 12:41:58.794 [INFO] [INFO] ++++++++++ Creating EntityUtils
2025-05-11 12:41:58.794 [INFO] [INFO] ++++++++++ EntityUtils custom_serializers: {}
2025-05-11 12:41:58.798 [INFO] [INFO] ++++++++++ Creating EntityUtils
2025-05-11 12:41:58.798 [INFO] [INFO] ++++++++++ EntityUtils custom_serializers: {}
2025-05-11 12:42:00.575 [INFO] [INFO] Setting up test environment...
2025-05-11 12:42:00.576 [INFO] [INFO] Removing .\.pytest_cache
2025-05-11 12:42:00.707 [INFO] [INFO] Test files in this session: {'c:\\Users\\Phil\\Desktop\\Projects\\shared-libs\\python\\errors\\tests\\test_error.py'}
2025-05-11 12:42:00.708 [INFO] [INFO] No Docker Compose files found for any test files. Continuing without Docker setup.
2025-05-11 12:42:00.714 [ERROR] [ERROR] App caught: An error happened in Postgres.connect: Connection refused (line 63)
c:\Users\Phil\Desktop\Projects\shared-libs\python\errors\tests\test_error.py connect line 63
c:\Users\Phil\Desktop\Projects\shared-libs\python\errors\tests\test_error.py connect line 63
2025-05-11 12:42:00.714 [INFO] [INFO] There was an error at the App level: division by zero
2025-05-11 12:42:00.715 [INFO] [INFO] Tearing down test environment...
2025-05-11 12:42:52.178 [INFO] [INFO] ++++++++++ Creating EntityUtils
2025-05-11 12:42:52.178 [INFO] [INFO] ++++++++++ EntityUtils custom_serializers: {}
2025-05-11 12:42:52.188 [INFO] [INFO] ++++++++++ Creating EntityUtils
2025-05-11 12:42:52.188 [INFO] [INFO] ++++++++++ EntityUtils custom_serializers: {}
2025-05-11 12:42:52.193 [INFO] [INFO] ++++++++++ Creating EntityUtils
2025-05-11 12:42:52.193 [INFO] [INFO] ++++++++++ EntityUtils custom_serializers: {}
2025-05-11 12:42:59.072 [INFO] [INFO] ++++++++++ Creating EntityUtils
2025-05-11 12:42:59.072 [INFO] [INFO] ++++++++++ EntityUtils custom_serializers: {}
2025-05-11 12:42:59.083 [INFO] [INFO] ++++++++++ Creating EntityUtils
2025-05-11 12:42:59.083 [INFO] [INFO] ++++++++++ EntityUtils custom_serializers: {}
2025-05-11 12:42:59.086 [INFO] [INFO] ++++++++++ Creating EntityUtils
2025-05-11 12:42:59.086 [INFO] [INFO] ++++++++++ EntityUtils custom_serializers: {}
2025-05-11 12:43:01.789 [INFO] [INFO] Setting up test environment...
2025-05-11 12:43:01.789 [INFO] [INFO] Removing .\.pytest_cache
2025-05-11 12:43:01.821 [INFO] [INFO] Test files in this session: {'c:\\Users\\Phil\\Desktop\\Projects\\shared-libs\\python\\errors\\tests\\test_error.py'}
2025-05-11 12:43:01.821 [INFO] [INFO] No Docker Compose files found for any test files. Continuing without Docker setup.
2025-05-11 12:43:01.823 [ERROR] [ERROR] App caught: An error happened in Postgres.connect: Connection refused (line 63)
Trace:
c:\Users\Phil\Desktop\Projects\shared-libs\python\errors\tests\test_error.py connect line 63
c:\Users\Phil\Desktop\Projects\shared-libs\python\errors\tests\test_error.py connect line 63
2025-05-11 12:43:01.823 [INFO] [INFO] There was an error at the App level: division by zero
2025-05-11 12:43:01.824 [INFO] [INFO] Tearing down test environment...
2025-05-11 12:46:58.974 [INFO] [INFO] ++++++++++ Creating EntityUtils
2025-05-11 12:46:58.974 [INFO] [INFO] ++++++++++ EntityUtils custom_serializers: {}
2025-05-11 12:46:58.982 [INFO] [INFO] ++++++++++ Creating EntityUtils
2025-05-11 12:46:58.982 [INFO] [INFO] ++++++++++ EntityUtils custom_serializers: {}
2025-05-11 12:46:58.986 [INFO] [INFO] ++++++++++ Creating EntityUtils
2025-05-11 12:46:58.986 [INFO] [INFO] ++++++++++ EntityUtils custom_serializers: {}
2025-05-11 12:47:21.287 [INFO] [INFO] ++++++++++ Creating EntityUtils
2025-05-11 12:47:21.287 [INFO] [INFO] ++++++++++ EntityUtils custom_serializers: {}
2025-05-11 12:47:21.299 [INFO] [INFO] ++++++++++ Creating EntityUtils
2025-05-11 12:47:21.299 [INFO] [INFO] ++++++++++ EntityUtils custom_serializers: {}
2025-05-11 12:47:21.303 [INFO] [INFO] ++++++++++ Creating EntityUtils
2025-05-11 12:47:21.303 [INFO] [INFO] ++++++++++ EntityUtils custom_serializers: {}
2025-05-11 12:47:27.465 [INFO] [INFO] ++++++++++ Creating EntityUtils
2025-05-11 12:47:27.465 [INFO] [INFO] ++++++++++ EntityUtils custom_serializers: {}
2025-05-11 12:47:27.477 [INFO] [INFO] ++++++++++ Creating EntityUtils
2025-05-11 12:47:27.477 [INFO] [INFO] ++++++++++ EntityUtils custom_serializers: {}
2025-05-11 12:47:27.482 [INFO] [INFO] ++++++++++ Creating EntityUtils
2025-05-11 12:47:27.483 [INFO] [INFO] ++++++++++ EntityUtils custom_serializers: {}
2025-05-11 12:47:32.603 [INFO] [INFO] Setting up test environment...
2025-05-11 12:47:32.604 [INFO] [INFO] Removing .\.pytest_cache
2025-05-11 12:47:32.637 [INFO] [INFO] Test files in this session: {'c:\\Users\\Phil\\Desktop\\Projects\\shared-libs\\python\\errors\\tests\\test_error.py'}
2025-05-11 12:47:32.637 [INFO] [INFO] No Docker Compose files found for any test files. Continuing without Docker setup.
2025-05-11 12:47:32.639 [ERROR] [ERROR] App caught: An error happened in Postgres.connect: Connection refused
Trace:
c:\Users\Phil\Desktop\Projects\shared-libs\python\errors\tests\test_error.py connect line 63
2025-05-11 12:47:32.639 [INFO] [INFO] There was an error at the App level: division by zero
2025-05-11 12:47:32.640 [INFO] [INFO] Tearing down test environment...
2025-05-11 12:52:44.492 [INFO] [INFO] ++++++++++ Creating EntityUtils
2025-05-11 12:52:44.492 [INFO] [INFO] ++++++++++ EntityUtils custom_serializers: {}
2025-05-11 12:52:44.501 [INFO] [INFO] ++++++++++ Creating EntityUtils
2025-05-11 12:52:44.501 [INFO] [INFO] ++++++++++ EntityUtils custom_serializers: {}
2025-05-11 12:52:44.505 [INFO] [INFO] ++++++++++ Creating EntityUtils
2025-05-11 12:52:44.505 [INFO] [INFO] ++++++++++ EntityUtils custom_serializers: {}
2025-05-11 12:53:04.394 [INFO] [INFO] ++++++++++ Creating EntityUtils
2025-05-11 12:53:04.394 [INFO] [INFO] ++++++++++ EntityUtils custom_serializers: {}
2025-05-11 12:53:04.402 [INFO] [INFO] ++++++++++ Creating EntityUtils
2025-05-11 12:53:04.402 [INFO] [INFO] ++++++++++ EntityUtils custom_serializers: {}
2025-05-11 12:53:04.406 [INFO] [INFO] ++++++++++ Creating EntityUtils
2025-05-11 12:53:04.406 [INFO] [INFO] ++++++++++ EntityUtils custom_serializers: {}
2025-05-11 12:53:13.831 [INFO] [INFO] Setting up test environment...
2025-05-11 12:53:13.832 [INFO] [INFO] Removing .\.pytest_cache
2025-05-11 12:53:13.863 [INFO] [INFO] Test files in this session: {'c:\\Users\\Phil\\Desktop\\Projects\\shared-libs\\python\\errors\\tests\\test_error.py'}
2025-05-11 12:53:13.864 [INFO] [INFO] No Docker Compose files found for any test files. Continuing without Docker setup.
2025-05-11 12:53:13.868 [ERROR] [ERROR] App caught: An error happened in Postgres.connect: Connection refused
Trace:
c:\Users\Phil\Desktop\Projects\shared-libs\python\errors\tests\test_error.py connect line 63
2025-05-11 12:53:13.868 [INFO] [INFO] There was an error at the App level: division by zero
2025-05-11 12:53:13.870 [INFO] [INFO] Tearing down test environment...
2025-05-11 12:53:52.512 [INFO] [INFO] ++++++++++ Creating EntityUtils
2025-05-11 12:53:52.513 [INFO] [INFO] ++++++++++ EntityUtils custom_serializers: {}
2025-05-11 12:53:52.522 [INFO] [INFO] ++++++++++ Creating EntityUtils
2025-05-11 12:53:52.522 [INFO] [INFO] ++++++++++ EntityUtils custom_serializers: {}
2025-05-11 12:53:52.526 [INFO] [INFO] ++++++++++ Creating EntityUtils
2025-05-11 12:53:52.526 [INFO] [INFO] ++++++++++ EntityUtils custom_serializers: {}
2025-05-11 12:53:55.731 [INFO] [INFO] Setting up test environment...
2025-05-11 12:53:55.731 [INFO] [INFO] Removing .\.pytest_cache
2025-05-11 12:53:55.762 [INFO] [INFO] Test files in this session: {'c:\\Users\\Phil\\Desktop\\Projects\\shared-libs\\python\\errors\\tests\\test_error.py'}
2025-05-11 12:53:55.763 [INFO] [INFO] No Docker Compose files found for any test files. Continuing without Docker setup.
2025-05-11 12:53:55.764 [ERROR] [ERROR] App caught: An error happened in Postgres.connect: Connection refused
MRO:
PytestPluginManager._hookexec -> _multicall -> pytest_pyfunc_call -> wrapperTrace:
c:\Users\Phil\Desktop\Projects\shared-libs\python\errors\tests\test_error.py connect line 63
2025-05-11 12:53:55.765 [INFO] [INFO] There was an error at the App level: division by zero
2025-05-11 12:53:55.766 [INFO] [INFO] Tearing down test environment...
2025-05-11 12:54:24.926 [INFO] [INFO] ++++++++++ Creating EntityUtils
2025-05-11 12:54:24.927 [INFO] [INFO] ++++++++++ EntityUtils custom_serializers: {}
2025-05-11 12:54:24.934 [INFO] [INFO] ++++++++++ Creating EntityUtils
2025-05-11 12:54:24.934 [INFO] [INFO] ++++++++++ EntityUtils custom_serializers: {}
2025-05-11 12:54:24.937 [INFO] [INFO] ++++++++++ Creating EntityUtils
2025-05-11 12:54:24.938 [INFO] [INFO] ++++++++++ EntityUtils custom_serializers: {}
2025-05-11 12:54:43.064 [INFO] [INFO] ++++++++++ Creating EntityUtils
2025-05-11 12:54:43.064 [INFO] [INFO] ++++++++++ EntityUtils custom_serializers: {}
2025-05-11 12:54:43.073 [INFO] [INFO] ++++++++++ Creating EntityUtils
2025-05-11 12:54:43.073 [INFO] [INFO] ++++++++++ EntityUtils custom_serializers: {}
2025-05-11 12:54:43.077 [INFO] [INFO] ++++++++++ Creating EntityUtils
2025-05-11 12:54:43.077 [INFO] [INFO] ++++++++++ EntityUtils custom_serializers: {}
2025-05-11 12:54:51.069 [INFO] [INFO] ++++++++++ Creating EntityUtils
2025-05-11 12:54:51.069 [INFO] [INFO] ++++++++++ EntityUtils custom_serializers: {}
2025-05-11 12:54:51.076 [INFO] [INFO] ++++++++++ Creating EntityUtils
2025-05-11 12:54:51.077 [INFO] [INFO] ++++++++++ EntityUtils custom_serializers: {}
2025-05-11 12:54:51.081 [INFO] [INFO] ++++++++++ Creating EntityUtils
2025-05-11 12:54:51.081 [INFO] [INFO] ++++++++++ EntityUtils custom_serializers: {}
2025-05-11 12:55:02.259 [INFO] [INFO] Setting up test environment...
2025-05-11 12:55:02.260 [INFO] [INFO] Removing .\.pytest_cache
2025-05-11 12:55:02.292 [INFO] [INFO] Test files in this session: {'c:\\Users\\Phil\\Desktop\\Projects\\shared-libs\\python\\errors\\tests\\test_error.py'}
2025-05-11 12:55:02.293 [INFO] [INFO] No Docker Compose files found for any test files. Continuing without Docker setup.
2025-05-11 12:55:02.295 [ERROR] [ERROR] App caught: An error happened in Postgres.connect: Connection refused
Call chain:PytestPluginManager._hookexec -> _multicall -> pytest_pyfunc_call -> wrapper
Trace:
c:\Users\Phil\Desktop\Projects\shared-libs\python\errors\tests\test_error.py connect line 63
2025-05-11 12:55:02.295 [INFO] [INFO] There was an error at the App level: division by zero
2025-05-11 12:55:02.296 [INFO] [INFO] Tearing down test environment...
2025-05-11 12:55:14.978 [INFO] [INFO] ++++++++++ Creating EntityUtils
2025-05-11 12:55:14.978 [INFO] [INFO] ++++++++++ EntityUtils custom_serializers: {}
2025-05-11 12:55:14.987 [INFO] [INFO] ++++++++++ Creating EntityUtils
2025-05-11 12:55:14.987 [INFO] [INFO] ++++++++++ EntityUtils custom_serializers: {}
2025-05-11 12:55:14.991 [INFO] [INFO] ++++++++++ Creating EntityUtils
2025-05-11 12:55:14.991 [INFO] [INFO] ++++++++++ EntityUtils custom_serializers: {}
2025-05-11 12:55:22.485 [INFO] [INFO] Setting up test environment...
2025-05-11 12:55:22.486 [INFO] [INFO] Removing .\.pytest_cache
2025-05-11 12:55:22.524 [INFO] [INFO] Test files in this session: {'c:\\Users\\Phil\\Desktop\\Projects\\shared-libs\\python\\errors\\tests\\test_error.py'}
2025-05-11 12:55:22.525 [INFO] [INFO] No Docker Compose files found for any test files. Continuing without Docker setup.
2025-05-11 12:55:22.528 [ERROR] [ERROR] App caught: An error happened in Postgres.connect: Connection refused
Call chain: PytestPluginManager._hookexec -> _multicall -> pytest_pyfunc_call -> wrapper
Trace:
c:\Users\Phil\Desktop\Projects\shared-libs\python\errors\tests\test_error.py connect line 63
2025-05-11 12:55:22.528 [INFO] [INFO] There was an error at the App level: division by zero
2025-05-11 12:55:22.529 [INFO] [INFO] Tearing down test environment...
2025-05-11 12:55:51.867 [INFO] [INFO] ++++++++++ Creating EntityUtils
2025-05-11 12:55:51.867 [INFO] [INFO] ++++++++++ EntityUtils custom_serializers: {}
2025-05-11 12:55:51.877 [INFO] [INFO] ++++++++++ Creating EntityUtils
2025-05-11 12:55:51.877 [INFO] [INFO] ++++++++++ EntityUtils custom_serializers: {}
2025-05-11 12:55:51.880 [INFO] [INFO] ++++++++++ Creating EntityUtils
2025-05-11 12:55:51.880 [INFO] [INFO] ++++++++++ EntityUtils custom_serializers: {}
2025-05-11 12:56:09.848 [INFO] [INFO] ++++++++++ Creating EntityUtils
2025-05-11 12:56:09.848 [INFO] [INFO] ++++++++++ EntityUtils custom_serializers: {}
2025-05-11 12:56:09.859 [INFO] [INFO] ++++++++++ Creating EntityUtils
2025-05-11 12:56:09.859 [INFO] [INFO] ++++++++++ EntityUtils custom_serializers: {}
2025-05-11 12:56:09.864 [INFO] [INFO] ++++++++++ Creating EntityUtils
2025-05-11 12:56:09.864 [INFO] [INFO] ++++++++++ EntityUtils custom_serializers: {}
2025-05-11 12:56:11.906 [INFO] [INFO] Setting up test environment...
2025-05-11 12:56:11.906 [INFO] [INFO] Removing .\.pytest_cache
2025-05-11 12:56:11.971 [INFO] [INFO] Test files in this session: {'c:\\Users\\Phil\\Desktop\\Projects\\shared-libs\\python\\errors\\tests\\test_error.py'}
2025-05-11 12:56:11.972 [INFO] [INFO] No Docker Compose files found for any test files. Continuing without Docker setup.
2025-05-11 12:56:11.975 [ERROR] [ERROR] App caught:
An error happened in Postgres.connect: Connection refused
Call chain: PytestPluginManager._hookexec -> _multicall -> pytest_pyfunc_call -> wrapper
Trace:
c:\Users\Phil\Desktop\Projects\shared-libs\python\errors\tests\test_error.py connect line 63
2025-05-11 12:56:11.975 [INFO] [INFO] There was an error at the App level: division by zero
2025-05-11 12:56:11.977 [INFO] [INFO] Tearing down test environment...
2025-05-11 12:57:18.862 [INFO] [INFO] ++++++++++ Creating EntityUtils
2025-05-11 12:57:18.862 [INFO] [INFO] ++++++++++ EntityUtils custom_serializers: {}
2025-05-11 12:57:18.874 [INFO] [INFO] ++++++++++ Creating EntityUtils
2025-05-11 12:57:18.874 [INFO] [INFO] ++++++++++ EntityUtils custom_serializers: {}
2025-05-11 12:57:18.879 [INFO] [INFO] ++++++++++ Creating EntityUtils
2025-05-11 12:57:18.879 [INFO] [INFO] ++++++++++ EntityUtils custom_serializers: {}
2025-05-11 12:57:20.683 [INFO] [INFO] Setting up test environment...
2025-05-11 12:57:20.683 [INFO] [INFO] Removing .\.pytest_cache
2025-05-11 12:57:20.732 [INFO] [INFO] Test files in this session: {'c:\\Users\\Phil\\Desktop\\Projects\\shared-libs\\python\\errors\\tests\\test_error.py'}
2025-05-11 12:57:20.733 [INFO] [INFO] No Docker Compose files found for any test files. Continuing without Docker setup.
2025-05-11 12:57:20.735 [ERROR] [ERROR] App caught:
An error happened in Postgres.connect: Connection refused
Call chain: unknown
Trace:
c:\Users\Phil\Desktop\Projects\shared-libs\python\errors\tests\test_error.py connect line 63
2025-05-11 12:57:20.736 [INFO] [INFO] There was an error at the App level: division by zero
2025-05-11 12:57:20.737 [INFO] [INFO] Tearing down test environment...
2025-05-11 13:02:24.989 [INFO] [INFO] ++++++++++ Creating EntityUtils
2025-05-11 13:02:24.990 [INFO] [INFO] ++++++++++ EntityUtils custom_serializers: {}
2025-05-11 13:02:25.028 [INFO] [INFO] ++++++++++ Creating EntityUtils
2025-05-11 13:02:25.028 [INFO] [INFO] ++++++++++ EntityUtils custom_serializers: {}
2025-05-11 13:02:25.034 [INFO] [INFO] ++++++++++ Creating EntityUtils
2025-05-11 13:02:25.034 [INFO] [INFO] ++++++++++ EntityUtils custom_serializers: {}
2025-05-11 13:02:33.858 [INFO] [INFO] ++++++++++ Creating EntityUtils
2025-05-11 13:02:33.858 [INFO] [INFO] ++++++++++ EntityUtils custom_serializers: {}
2025-05-11 13:02:33.867 [INFO] [INFO] ++++++++++ Creating EntityUtils
2025-05-11 13:02:33.867 [INFO] [INFO] ++++++++++ EntityUtils custom_serializers: {}
2025-05-11 13:02:33.870 [INFO] [INFO] ++++++++++ Creating EntityUtils
2025-05-11 13:02:33.870 [INFO] [INFO] ++++++++++ EntityUtils custom_serializers: {}
2025-05-11 13:02:39.830 [INFO] [INFO] Setting up test environment...
2025-05-11 13:02:39.830 [INFO] [INFO] Removing .\.pytest_cache
2025-05-11 13:02:39.859 [INFO] [INFO] Test files in this session: {'c:\\Users\\Phil\\Desktop\\Projects\\shared-libs\\python\\errors\\tests\\test_error.py'}
2025-05-11 13:02:39.859 [INFO] [INFO] No Docker Compose files found for any test files. Continuing without Docker setup.
2025-05-11 13:02:39.874 [ERROR] [ERROR] App caught:
An error happened in Postgres.connect: test_try_catch.<locals>.Database.connect() missing 1 required positional argument: 'connection_string'
Call chain: unknown
Trace:
c:\Users\Phil\Desktop\Projects\shared-libs\python\errors\try_catch.py wrapper line 24
2025-05-11 13:02:39.874 [INFO] [INFO] There was an error at the App level: division by zero
2025-05-11 13:02:39.875 [INFO] [INFO] Tearing down test environment...
2025-05-11 13:02:54.265 [INFO] [INFO] ++++++++++ Creating EntityUtils
2025-05-11 13:02:54.265 [INFO] [INFO] ++++++++++ EntityUtils custom_serializers: {}
2025-05-11 13:02:54.274 [INFO] [INFO] ++++++++++ Creating EntityUtils
2025-05-11 13:02:54.274 [INFO] [INFO] ++++++++++ EntityUtils custom_serializers: {}
2025-05-11 13:02:54.277 [INFO] [INFO] ++++++++++ Creating EntityUtils
2025-05-11 13:02:54.277 [INFO] [INFO] ++++++++++ EntityUtils custom_serializers: {}
2025-05-11 13:02:58.827 [INFO] [INFO] ++++++++++ Creating EntityUtils
2025-05-11 13:02:58.827 [INFO] [INFO] ++++++++++ EntityUtils custom_serializers: {}
2025-05-11 13:02:58.840 [INFO] [INFO] ++++++++++ Creating EntityUtils
2025-05-11 13:02:58.840 [INFO] [INFO] ++++++++++ EntityUtils custom_serializers: {}
2025-05-11 13:02:58.845 [INFO] [INFO] ++++++++++ Creating EntityUtils
2025-05-11 13:02:58.845 [INFO] [INFO] ++++++++++ EntityUtils custom_serializers: {}
2025-05-11 13:03:00.885 [INFO] [INFO] Setting up test environment...
2025-05-11 13:03:00.885 [INFO] [INFO] Removing .\.pytest_cache
2025-05-11 13:03:00.918 [INFO] [INFO] Test files in this session: {'c:\\Users\\Phil\\Desktop\\Projects\\shared-libs\\python\\errors\\tests\\test_error.py'}
2025-05-11 13:03:00.919 [INFO] [INFO] No Docker Compose files found for any test files. Continuing without Docker setup.
2025-05-11 13:03:00.922 [ERROR] [ERROR] App caught:
An error happened in Postgres.connect: test_try_catch.<locals>.Database.connect() missing 1 required positional argument: 'connection_string'
Call chain: unknown
Trace:
c:\Users\Phil\Desktop\Projects\shared-libs\python\errors\try_catch.py wrapper line 24
2025-05-11 13:03:00.922 [INFO] [INFO] There was an error at the App level: division by zero
2025-05-11 13:03:00.923 [INFO] [INFO] Tearing down test environment...
2025-05-11 13:03:14.590 [INFO] [INFO] ++++++++++ Creating EntityUtils
2025-05-11 13:03:14.590 [INFO] [INFO] ++++++++++ EntityUtils custom_serializers: {}
2025-05-11 13:03:14.598 [INFO] [INFO] ++++++++++ Creating EntityUtils
2025-05-11 13:03:14.598 [INFO] [INFO] ++++++++++ EntityUtils custom_serializers: {}
2025-05-11 13:03:14.602 [INFO] [INFO] ++++++++++ Creating EntityUtils
2025-05-11 13:03:14.602 [INFO] [INFO] ++++++++++ EntityUtils custom_serializers: {}
2025-05-11 13:03:35.259 [INFO] [INFO] ++++++++++ Creating EntityUtils
2025-05-11 13:03:35.259 [INFO] [INFO] ++++++++++ EntityUtils custom_serializers: {}
2025-05-11 13:03:35.272 [INFO] [INFO] ++++++++++ Creating EntityUtils
2025-05-11 13:03:35.272 [INFO] [INFO] ++++++++++ EntityUtils custom_serializers: {}
2025-05-11 13:03:35.276 [INFO] [INFO] ++++++++++ Creating EntityUtils
2025-05-11 13:03:35.276 [INFO] [INFO] ++++++++++ EntityUtils custom_serializers: {}
2025-05-11 13:03:37.062 [INFO] [INFO] Setting up test environment...
2025-05-11 13:03:37.062 [INFO] [INFO] Removing .\.pytest_cache
2025-05-11 13:03:37.110 [INFO] [INFO] Test files in this session: {'c:\\Users\\Phil\\Desktop\\Projects\\shared-libs\\python\\errors\\tests\\test_error.py'}
2025-05-11 13:03:37.111 [INFO] [INFO] No Docker Compose files found for any test files. Continuing without Docker setup.
2025-05-11 13:03:37.113 [ERROR] [ERROR] App caught:
An error happened in Postgres.connect: Connection refused
Call chain: unknown
Trace:
c:\Users\Phil\Desktop\Projects\shared-libs\python\errors\tests\test_error.py connect line 63
2025-05-11 13:03:37.113 [INFO] [INFO] There was an error at the App level: division by zero
2025-05-11 13:03:37.115 [INFO] [INFO] Tearing down test environment...
2025-05-11 13:05:56.815 [INFO] [INFO] ++++++++++ Creating EntityUtils
2025-05-11 13:05:56.816 [INFO] [INFO] ++++++++++ EntityUtils custom_serializers: {}
2025-05-11 13:05:56.825 [INFO] [INFO] ++++++++++ Creating EntityUtils
2025-05-11 13:05:56.825 [INFO] [INFO] ++++++++++ EntityUtils custom_serializers: {}
2025-05-11 13:05:56.830 [INFO] [INFO] ++++++++++ Creating EntityUtils
2025-05-11 13:05:56.830 [INFO] [INFO] ++++++++++ EntityUtils custom_serializers: {}
2025-05-11 13:05:57.702 [INFO] [INFO] Setting up test environment...
2025-05-11 13:05:57.702 [INFO] [INFO] Removing .\.pytest_cache
2025-05-11 13:05:57.739 [INFO] [INFO] Test files in this session: {'c:\\Users\\Phil\\Desktop\\Projects\\shared-libs\\python\\errors\\tests\\test_error.py'}
2025-05-11 13:05:57.740 [INFO] [INFO] No Docker Compose files found for any test files. Continuing without Docker setup.
2025-05-11 13:05:57.878 [ERROR] [ERROR] Error in Postgres.connect (defined in Database): Connection refused
2025-05-11 13:05:57.878 [ERROR] [ERROR] App caught:
An error happened in Postgres.connect (defined in Database): Connection refused
Call chain: Postgres.reconnect -> Postgres.connect (defined in Database)
Trace:
c:\Users\Phil\Desktop\Projects\shared-libs\python\errors\tests\test_error.py connect line 63
2025-05-11 13:05:57.879 [INFO] [INFO] There was an error at the App level: division by zero
2025-05-11 13:05:57.880 [INFO] [INFO] Tearing down test environment...
2025-05-11 13:08:03.583 [INFO] [INFO] ++++++++++ Creating EntityUtils
2025-05-11 13:08:03.583 [INFO] [INFO] ++++++++++ EntityUtils custom_serializers: {}
2025-05-11 13:08:03.590 [INFO] [INFO] ++++++++++ Creating EntityUtils
2025-05-11 13:08:03.591 [INFO] [INFO] ++++++++++ EntityUtils custom_serializers: {}
2025-05-11 13:08:03.594 [INFO] [INFO] ++++++++++ Creating EntityUtils
2025-05-11 13:08:03.594 [INFO] [INFO] ++++++++++ EntityUtils custom_serializers: {}
2025-05-11 13:08:12.274 [INFO] [INFO] ++++++++++ Creating EntityUtils
2025-05-11 13:08:12.274 [INFO] [INFO] ++++++++++ EntityUtils custom_serializers: {}
2025-05-11 13:08:12.283 [INFO] [INFO] ++++++++++ Creating EntityUtils
2025-05-11 13:08:12.283 [INFO] [INFO] ++++++++++ EntityUtils custom_serializers: {}
2025-05-11 13:08:12.287 [INFO] [INFO] ++++++++++ Creating EntityUtils
2025-05-11 13:08:12.287 [INFO] [INFO] ++++++++++ EntityUtils custom_serializers: {}
2025-05-11 13:08:30.127 [INFO] [INFO] Setting up test environment...
2025-05-11 13:08:30.127 [INFO] [INFO] Removing .\.pytest_cache
2025-05-11 13:08:30.158 [INFO] [INFO] Test files in this session: {'c:\\Users\\Phil\\Desktop\\Projects\\shared-libs\\python\\errors\\tests\\test_error.py'}
2025-05-11 13:08:30.159 [INFO] [INFO] No Docker Compose files found for any test files. Continuing without Docker setup.
2025-05-11 13:08:30.161 [ERROR] [ERROR] Error in Postgres.connect (defined in Database): Connection refused
2025-05-11 13:08:30.363 [ERROR] [ERROR] Error in Postgres.reconnect: maximum recursion depth exceeded
2025-05-11 13:08:30.456 [ERROR] [ERROR] There was an error at the App level: maximum recursion depth exceeded
2025-05-11 13:08:30.456 [INFO] [INFO] There was an error at the App level: division by zero
2025-05-11 13:08:30.457 [INFO] [INFO] Tearing down test environment...
2025-05-11 13:09:41.529 [INFO] [INFO] ++++++++++ Creating EntityUtils
2025-05-11 13:09:41.529 [INFO] [INFO] ++++++++++ EntityUtils custom_serializers: {}
2025-05-11 13:09:41.541 [INFO] [INFO] ++++++++++ Creating EntityUtils
2025-05-11 13:09:41.541 [INFO] [INFO] ++++++++++ EntityUtils custom_serializers: {}
2025-05-11 13:09:41.545 [INFO] [INFO] ++++++++++ Creating EntityUtils
2025-05-11 13:09:41.545 [INFO] [INFO] ++++++++++ EntityUtils custom_serializers: {}
2025-05-11 13:09:43.001 [INFO] [INFO] Setting up test environment...
2025-05-11 13:09:43.001 [INFO] [INFO] Removing .\.pytest_cache
2025-05-11 13:09:43.036 [INFO] [INFO] Test files in this session: {'c:\\Users\\Phil\\Desktop\\Projects\\shared-libs\\python\\errors\\tests\\test_error.py'}
2025-05-11 13:09:43.037 [INFO] [INFO] No Docker Compose files found for any test files. Continuing without Docker setup.
2025-05-11 13:09:43.039 [ERROR] [ERROR] Error in Postgres.connect (defined in Database): Connection refused
2025-05-11 13:09:43.186 [ERROR] [ERROR] App caught:
An error happened in Postgres.connect (defined in Database): Connection refused
Call chain: recursion detected -> Postgres.reconnect
Trace:
c:\Users\Phil\Desktop\Projects\shared-libs\python\errors\tests\test_error.py connect line 63
2025-05-11 13:09:43.187 [INFO] [INFO] There was an error at the App level: division by zero
2025-05-11 13:09:43.188 [INFO] [INFO] Tearing down test environment...
2025-05-11 13:10:19.146 [INFO] [INFO] ++++++++++ Creating EntityUtils
2025-05-11 13:10:19.146 [INFO] [INFO] ++++++++++ EntityUtils custom_serializers: {}
2025-05-11 13:10:19.156 [INFO] [INFO] ++++++++++ Creating EntityUtils
2025-05-11 13:10:19.156 [INFO] [INFO] ++++++++++ EntityUtils custom_serializers: {}
2025-05-11 13:10:19.159 [INFO] [INFO] ++++++++++ Creating EntityUtils
2025-05-11 13:10:19.160 [INFO] [INFO] ++++++++++ EntityUtils custom_serializers: {}
2025-05-11 13:10:25.257 [INFO] [INFO] Setting up test environment...
2025-05-11 13:10:25.258 [INFO] [INFO] Removing .\.pytest_cache
2025-05-11 13:10:25.290 [INFO] [INFO] Test files in this session: {'c:\\Users\\Phil\\Desktop\\Projects\\shared-libs\\python\\errors\\tests\\test_error.py'}
2025-05-11 13:10:25.292 [INFO] [INFO] No Docker Compose files found for any test files. Continuing without Docker setup.
2025-05-11 13:10:25.294 [ERROR] [ERROR] Error in Postgres.connect: Connection refused
2025-05-11 13:10:25.404 [ERROR] [ERROR] Error in Postgres.reconnect: Connection refused
2025-05-11 13:10:25.405 [ERROR] [ERROR] There was an error at the App level: Connection refused
2025-05-11 13:10:25.405 [INFO] [INFO] There was an error at the App level: division by zero
2025-05-11 13:10:25.408 [INFO] [INFO] Tearing down test environment...
2025-05-11 13:11:17.591 [INFO] [INFO] ++++++++++ Creating EntityUtils
2025-05-11 13:11:17.591 [INFO] [INFO] ++++++++++ EntityUtils custom_serializers: {}
2025-05-11 13:11:17.602 [INFO] [INFO] ++++++++++ Creating EntityUtils
2025-05-11 13:11:17.602 [INFO] [INFO] ++++++++++ EntityUtils custom_serializers: {}
2025-05-11 13:11:17.607 [INFO] [INFO] ++++++++++ Creating EntityUtils
2025-05-11 13:11:17.607 [INFO] [INFO] ++++++++++ EntityUtils custom_serializers: {}
2025-05-11 13:11:18.780 [INFO] [INFO] Setting up test environment...
2025-05-11 13:11:18.781 [INFO] [INFO] Removing .\.pytest_cache
2025-05-11 13:11:18.837 [INFO] [INFO] Test files in this session: {'c:\\Users\\Phil\\Desktop\\Projects\\shared-libs\\python\\errors\\tests\\test_error.py'}
2025-05-11 13:11:18.839 [INFO] [INFO] No Docker Compose files found for any test files. Continuing without Docker setup.
2025-05-11 13:11:18.841 [ERROR] [ERROR] Error in Postgres.connect: Connection refused
2025-05-11 13:11:19.024 [ERROR] [ERROR] There was an error at the App level: Connection refused
2025-05-11 13:11:19.024 [INFO] [INFO] There was an error at the App level: division by zero
2025-05-11 13:11:19.026 [INFO] [INFO] Tearing down test environment...
2025-05-11 13:12:46.344 [INFO] [INFO] ++++++++++ Creating EntityUtils
2025-05-11 13:12:46.345 [INFO] [INFO] ++++++++++ EntityUtils custom_serializers: {}
2025-05-11 13:12:46.357 [INFO] [INFO] ++++++++++ Creating EntityUtils
2025-05-11 13:12:46.358 [INFO] [INFO] ++++++++++ EntityUtils custom_serializers: {}
2025-05-11 13:12:46.362 [INFO] [INFO] ++++++++++ Creating EntityUtils
2025-05-11 13:12:46.362 [INFO] [INFO] ++++++++++ EntityUtils custom_serializers: {}
2025-05-11 13:12:48.549 [INFO] [INFO] Setting up test environment...
2025-05-11 13:12:48.550 [INFO] [INFO] Removing .\.pytest_cache
2025-05-11 13:12:48.580 [INFO] [INFO] Test files in this session: {'c:\\Users\\Phil\\Desktop\\Projects\\shared-libs\\python\\errors\\tests\\test_error.py'}
2025-05-11 13:12:48.581 [INFO] [INFO] No Docker Compose files found for any test files. Continuing without Docker setup.
2025-05-11 13:12:48.582 [ERROR] [ERROR] Error in Postgres.connect: Connection refused
2025-05-11 13:12:48.984 [INFO] [INFO] Tearing down test environment...
2025-05-11 13:14:32.722 [INFO] [INFO] ++++++++++ Creating EntityUtils
2025-05-11 13:14:32.722 [INFO] [INFO] ++++++++++ EntityUtils custom_serializers: {}
2025-05-11 13:14:32.735 [INFO] [INFO] ++++++++++ Creating EntityUtils
2025-05-11 13:14:32.735 [INFO] [INFO] ++++++++++ EntityUtils custom_serializers: {}
2025-05-11 13:14:32.739 [INFO] [INFO] ++++++++++ Creating EntityUtils
2025-05-11 13:14:32.739 [INFO] [INFO] ++++++++++ EntityUtils custom_serializers: {}
2025-05-11 13:14:33.936 [INFO] [INFO] Setting up test environment...
2025-05-11 13:14:33.936 [INFO] [INFO] Removing .\.pytest_cache
2025-05-11 13:14:33.979 [INFO] [INFO] Test files in this session: {'c:\\Users\\Phil\\Desktop\\Projects\\shared-libs\\python\\errors\\tests\\test_error.py'}
2025-05-11 13:14:33.980 [INFO] [INFO] No Docker Compose files found for any test files. Continuing without Docker setup.
2025-05-11 13:14:33.981 [ERROR] [ERROR] Error in Postgres.connect: Connection refused
2025-05-11 13:14:34.145 [INFO] [INFO] Tearing down test environment...
2025-05-11 13:15:59.755 [INFO] [INFO] ++++++++++ Creating EntityUtils
2025-05-11 13:15:59.756 [INFO] [INFO] ++++++++++ EntityUtils custom_serializers: {}
2025-05-11 13:15:59.761 [INFO] [INFO] ++++++++++ Creating EntityUtils
2025-05-11 13:15:59.761 [INFO] [INFO] ++++++++++ EntityUtils custom_serializers: {}
2025-05-11 13:15:59.764 [INFO] [INFO] ++++++++++ Creating EntityUtils
2025-05-11 13:15:59.764 [INFO] [INFO] ++++++++++ EntityUtils custom_serializers: {}
2025-05-11 13:16:22.532 [INFO] [INFO] ++++++++++ Creating EntityUtils
2025-05-11 13:16:22.532 [INFO] [INFO] ++++++++++ EntityUtils custom_serializers: {}
2025-05-11 13:16:22.545 [INFO] [INFO] ++++++++++ Creating EntityUtils
2025-05-11 13:16:22.545 [INFO] [INFO] ++++++++++ EntityUtils custom_serializers: {}
2025-05-11 13:16:22.549 [INFO] [INFO] ++++++++++ Creating EntityUtils
2025-05-11 13:16:22.549 [INFO] [INFO] ++++++++++ EntityUtils custom_serializers: {}
2025-05-11 13:16:30.497 [INFO] [INFO] ++++++++++ Creating EntityUtils
2025-05-11 13:16:30.498 [INFO] [INFO] ++++++++++ EntityUtils custom_serializers: {}
2025-05-11 13:16:30.505 [INFO] [INFO] ++++++++++ Creating EntityUtils
2025-05-11 13:16:30.505 [INFO] [INFO] ++++++++++ EntityUtils custom_serializers: {}
2025-05-11 13:16:30.508 [INFO] [INFO] ++++++++++ Creating EntityUtils
2025-05-11 13:16:30.508 [INFO] [INFO] ++++++++++ EntityUtils custom_serializers: {}
2025-05-11 13:16:33.455 [INFO] [INFO] Setting up test environment...
2025-05-11 13:16:33.455 [INFO] [INFO] Removing .\.pytest_cache
2025-05-11 13:16:33.486 [INFO] [INFO] Test files in this session: {'c:\\Users\\Phil\\Desktop\\Projects\\shared-libs\\python\\errors\\tests\\test_error.py'}
2025-05-11 13:16:33.486 [INFO] [INFO] No Docker Compose files found for any test files. Continuing without Docker setup.
2025-05-11 13:16:33.487 [ERROR] [ERROR] Error in Postgres.connect: Connection refused
2025-05-11 13:16:33.488 [ERROR] [ERROR] App caught error: An error happened in Postgres.connect: Connection refused
Call chain: Postgres.connect
Trace:
c:\Users\Phil\Desktop\Projects\shared-libs\python\errors\tests\test_error.py connect line 62
2025-05-11 13:16:33.488 [ERROR] [ERROR] Description: An error happened in Postgres.connect: Connection refused
2025-05-11 13:16:33.488 [ERROR] [ERROR] Call chain: Postgres.connect
2025-05-11 13:16:33.488 [ERROR] [ERROR] Trace: ['c:\\Users\\Phil\\Desktop\\Projects\\shared-libs\\python\\errors\\tests\\test_error.py connect line 62']
2025-05-11 13:16:33.489 [INFO] [INFO] Tearing down test environment...
2025-05-11 13:17:36.451 [INFO] [INFO] ++++++++++ Creating EntityUtils
2025-05-11 13:17:36.451 [INFO] [INFO] ++++++++++ EntityUtils custom_serializers: {}
2025-05-11 13:17:36.458 [INFO] [INFO] ++++++++++ Creating EntityUtils
2025-05-11 13:17:36.458 [INFO] [INFO] ++++++++++ EntityUtils custom_serializers: {}
2025-05-11 13:17:36.462 [INFO] [INFO] ++++++++++ Creating EntityUtils
2025-05-11 13:17:36.462 [INFO] [INFO] ++++++++++ EntityUtils custom_serializers: {}
2025-05-11 13:18:09.302 [INFO] [INFO] ++++++++++ Creating EntityUtils
2025-05-11 13:18:09.302 [INFO] [INFO] ++++++++++ EntityUtils custom_serializers: {}
2025-05-11 13:18:09.312 [INFO] [INFO] ++++++++++ Creating EntityUtils
2025-05-11 13:18:09.312 [INFO] [INFO] ++++++++++ EntityUtils custom_serializers: {}
2025-05-11 13:18:09.315 [INFO] [INFO] ++++++++++ Creating EntityUtils
2025-05-11 13:18:09.315 [INFO] [INFO] ++++++++++ EntityUtils custom_serializers: {}
2025-05-11 13:18:32.917 [INFO] [INFO] ++++++++++ Creating EntityUtils
2025-05-11 13:18:32.917 [INFO] [INFO] ++++++++++ EntityUtils custom_serializers: {}
2025-05-11 13:18:32.931 [INFO] [INFO] ++++++++++ Creating EntityUtils
2025-05-11 13:18:32.931 [INFO] [INFO] ++++++++++ EntityUtils custom_serializers: {}
2025-05-11 13:18:32.935 [INFO] [INFO] ++++++++++ Creating EntityUtils
2025-05-11 13:18:32.936 [INFO] [INFO] ++++++++++ EntityUtils custom_serializers: {}
2025-05-11 13:18:34.588 [INFO] [INFO] Setting up test environment...
2025-05-11 13:18:34.589 [INFO] [INFO] Removing .\.pytest_cache
2025-05-11 13:18:34.627 [INFO] [INFO] Test files in this session: {'c:\\Users\\Phil\\Desktop\\Projects\\shared-libs\\python\\errors\\tests\\test_error.py'}
2025-05-11 13:18:34.628 [INFO] [INFO] No Docker Compose files found for any test files. Continuing without Docker setup.
2025-05-11 13:18:34.632 [ERROR] [ERROR] App caught error: An error happened in Postgres.connect: Connection refused
Call chain: Postgres.connect
Trace:
c:\Users\Phil\Desktop\Projects\shared-libs\python\errors\tests\test_error.py connect line 62
2025-05-11 13:18:34.632 [ERROR] [ERROR] Description: An error happened in Postgres.connect: Connection refused
2025-05-11 13:18:34.632 [ERROR] [ERROR] Call chain: Postgres.connect
2025-05-11 13:18:34.632 [ERROR] [ERROR] Trace: ['c:\\Users\\Phil\\Desktop\\Projects\\shared-libs\\python\\errors\\tests\\test_error.py connect line 62']
2025-05-11 13:18:34.633 [INFO] [INFO] Tearing down test environment...
2025-05-11 13:18:50.214 [INFO] [INFO] ++++++++++ Creating EntityUtils
2025-05-11 13:18:50.214 [INFO] [INFO] ++++++++++ EntityUtils custom_serializers: {}
2025-05-11 13:18:50.224 [INFO] [INFO] ++++++++++ Creating EntityUtils
2025-05-11 13:18:50.224 [INFO] [INFO] ++++++++++ EntityUtils custom_serializers: {}
2025-05-11 13:18:50.228 [INFO] [INFO] ++++++++++ Creating EntityUtils
2025-05-11 13:18:50.228 [INFO] [INFO] ++++++++++ EntityUtils custom_serializers: {}
2025-05-11 13:18:51.545 [INFO] [INFO] Setting up test environment...
2025-05-11 13:18:51.546 [INFO] [INFO] Removing .\.pytest_cache
2025-05-11 13:18:51.581 [INFO] [INFO] Test files in this session: {'c:\\Users\\Phil\\Desktop\\Projects\\shared-libs\\python\\errors\\tests\\test_error.py'}
2025-05-11 13:18:51.582 [INFO] [INFO] No Docker Compose files found for any test files. Continuing without Docker setup.
2025-05-11 13:18:51.584 [ERROR] [ERROR] App caught error: An error happened in Postgres.connect: Connection refused
Call chain: Postgres.connect -> Postgres.reconnect
Trace:
c:\Users\Phil\Desktop\Projects\shared-libs\python\errors\tests\test_error.py connect line 62
2025-05-11 13:18:51.584 [ERROR] [ERROR] Description: An error happened in Postgres.connect: Connection refused
2025-05-11 13:18:51.584 [ERROR] [ERROR] Call chain: Postgres.connect -> Postgres.reconnect
2025-05-11 13:18:51.585 [ERROR] [ERROR] Trace: ['c:\\Users\\Phil\\Desktop\\Projects\\shared-libs\\python\\errors\\tests\\test_error.py connect line 62']
2025-05-11 13:18:51.586 [INFO] [INFO] Tearing down test environment...
2025-05-11 13:20:32.925 [INFO] [INFO] ++++++++++ Creating EntityUtils
2025-05-11 13:20:32.926 [INFO] [INFO] ++++++++++ EntityUtils custom_serializers: {}
2025-05-11 13:20:32.934 [INFO] [INFO] ++++++++++ Creating EntityUtils
2025-05-11 13:20:32.934 [INFO] [INFO] ++++++++++ EntityUtils custom_serializers: {}
2025-05-11 13:20:32.938 [INFO] [INFO] ++++++++++ Creating EntityUtils
2025-05-11 13:20:32.938 [INFO] [INFO] ++++++++++ EntityUtils custom_serializers: {}
2025-05-11 13:20:43.355 [INFO] [INFO] ++++++++++ Creating EntityUtils
2025-05-11 13:20:43.355 [INFO] [INFO] ++++++++++ EntityUtils custom_serializers: {}
2025-05-11 13:20:43.365 [INFO] [INFO] ++++++++++ Creating EntityUtils
2025-05-11 13:20:43.365 [INFO] [INFO] ++++++++++ EntityUtils custom_serializers: {}
2025-05-11 13:20:43.368 [INFO] [INFO] ++++++++++ Creating EntityUtils
2025-05-11 13:20:43.368 [INFO] [INFO] ++++++++++ EntityUtils custom_serializers: {}
2025-05-11 13:20:52.246 [INFO] [INFO] ++++++++++ Creating EntityUtils
2025-05-11 13:20:52.246 [INFO] [INFO] ++++++++++ EntityUtils custom_serializers: {}
2025-05-11 13:20:52.252 [INFO] [INFO] ++++++++++ Creating EntityUtils
2025-05-11 13:20:52.252 [INFO] [INFO] ++++++++++ EntityUtils custom_serializers: {}
2025-05-11 13:20:52.255 [INFO] [INFO] ++++++++++ Creating EntityUtils
2025-05-11 13:20:52.255 [INFO] [INFO] ++++++++++ EntityUtils custom_serializers: {}
2025-05-11 13:20:55.942 [INFO] [INFO] Setting up test environment...
2025-05-11 13:20:55.942 [INFO] [INFO] Removing .\.pytest_cache
2025-05-11 13:20:55.976 [INFO] [INFO] Test files in this session: {'c:\\Users\\Phil\\Desktop\\Projects\\shared-libs\\python\\errors\\tests\\test_error.py'}
2025-05-11 13:20:55.977 [INFO] [INFO] No Docker Compose files found for any test files. Continuing without Docker setup.
2025-05-11 13:20:55.978 [ERROR] [ERROR] App caught error:
An error happened in Postgres.connect: Connection refused
Call chain: Postgres.connect -> Postgres.reconnect -> do
Trace:
c:\Users\Phil\Desktop\Projects\shared-libs\python\errors\tests\test_error.py connect line 62
2025-05-11 13:20:55.979 [INFO] [INFO] Tearing down test environment...
2025-05-11 13:24:40.034 [INFO] [INFO] ++++++++++ Creating EntityUtils
2025-05-11 13:24:40.034 [INFO] [INFO] ++++++++++ EntityUtils custom_serializers: {}
2025-05-11 13:24:40.042 [INFO] [INFO] ++++++++++ Creating EntityUtils
2025-05-11 13:24:40.042 [INFO] [INFO] ++++++++++ EntityUtils custom_serializers: {}
2025-05-11 13:24:40.046 [INFO] [INFO] ++++++++++ Creating EntityUtils
2025-05-11 13:24:40.046 [INFO] [INFO] ++++++++++ EntityUtils custom_serializers: {}
2025-05-11 13:24:41.104 [INFO] [INFO] Setting up test environment...
2025-05-11 13:24:41.104 [INFO] [INFO] Removing .\.pytest_cache
2025-05-11 13:24:41.143 [INFO] [INFO] Test files in this session: {'c:\\Users\\Phil\\Desktop\\Projects\\shared-libs\\python\\errors\\tests\\test_error.py'}
2025-05-11 13:24:41.143 [INFO] [INFO] No Docker Compose files found for any test files. Continuing without Docker setup.
2025-05-11 13:24:41.146 [ERROR] [ERROR] App caught error:
An error happened in Database.connect: Connection refused
Call chain: Database.connect -> Postgres.reconnect -> do
Trace:
c:\Users\Phil\Desktop\Projects\shared-libs\python\errors\tests\test_error.py connect line 62
2025-05-11 13:24:41.147 [INFO] [INFO] Tearing down test environment...
2025-05-11 13:28:36.663 [INFO] [INFO] ++++++++++ Creating EntityUtils
2025-05-11 13:28:36.663 [INFO] [INFO] ++++++++++ EntityUtils custom_serializers: {}
2025-05-11 13:28:36.671 [INFO] [INFO] ++++++++++ Creating EntityUtils
2025-05-11 13:28:36.671 [INFO] [INFO] ++++++++++ EntityUtils custom_serializers: {}
2025-05-11 13:28:36.674 [INFO] [INFO] ++++++++++ Creating EntityUtils
2025-05-11 13:28:36.674 [INFO] [INFO] ++++++++++ EntityUtils custom_serializers: {}
2025-05-11 13:30:43.100 [INFO] [INFO] ++++++++++ Creating EntityUtils
2025-05-11 13:30:43.100 [INFO] [INFO] ++++++++++ EntityUtils custom_serializers: {}
2025-05-11 13:30:43.111 [INFO] [INFO] ++++++++++ Creating EntityUtils
2025-05-11 13:30:43.111 [INFO] [INFO] ++++++++++ EntityUtils custom_serializers: {}
2025-05-11 13:30:43.115 [INFO] [INFO] ++++++++++ Creating EntityUtils
2025-05-11 13:30:43.115 [INFO] [INFO] ++++++++++ EntityUtils custom_serializers: {}
2025-05-11 13:30:48.575 [INFO] [INFO] Setting up test environment...
2025-05-11 13:30:48.576 [INFO] [INFO] Removing .\.pytest_cache
2025-05-11 13:30:48.604 [INFO] [INFO] Test files in this session: {'c:\\Users\\Phil\\Desktop\\Projects\\shared-libs\\python\\errors\\tests\\test_error.py'}
2025-05-11 13:30:48.605 [INFO] [INFO] No Docker Compose files found for any test files. Continuing without Docker setup.
2025-05-11 13:30:48.607 [ERROR] [ERROR] App caught error:
An error happened in Database.connect: Connection refused
Call chain: Database.connect -> Postgres.reconnect -> do
Trace:
c:\Users\Phil\Desktop\Projects\shared-libs\python\errors\tests\test_error.py connect line 62
2025-05-11 13:30:48.610 [INFO] [INFO] Tearing down test environment...
2025-05-11 13:33:49.070 [INFO] [INFO] ++++++++++ Creating EntityUtils
2025-05-11 13:33:49.071 [INFO] [INFO] ++++++++++ EntityUtils custom_serializers: {}
2025-05-11 13:33:49.078 [INFO] [INFO] ++++++++++ Creating EntityUtils
2025-05-11 13:33:49.078 [INFO] [INFO] ++++++++++ EntityUtils custom_serializers: {}
2025-05-11 13:33:49.082 [INFO] [INFO] ++++++++++ Creating EntityUtils
2025-05-11 13:33:49.082 [INFO] [INFO] ++++++++++ EntityUtils custom_serializers: {}
2025-05-11 13:33:58.434 [INFO] [INFO] ++++++++++ Creating EntityUtils
2025-05-11 13:33:58.434 [INFO] [INFO] ++++++++++ EntityUtils custom_serializers: {}
2025-05-11 13:33:58.445 [INFO] [INFO] ++++++++++ Creating EntityUtils
2025-05-11 13:33:58.446 [INFO] [INFO] ++++++++++ EntityUtils custom_serializers: {}
2025-05-11 13:33:58.449 [INFO] [INFO] ++++++++++ Creating EntityUtils
2025-05-11 13:33:58.449 [INFO] [INFO] ++++++++++ EntityUtils custom_serializers: {}
2025-05-11 13:34:04.423 [INFO] [INFO] Setting up test environment...
2025-05-11 13:34:04.423 [INFO] [INFO] Removing .\.pytest_cache
2025-05-11 13:34:04.460 [INFO] [INFO] Test files in this session: {'c:\\Users\\Phil\\Desktop\\Projects\\shared-libs\\python\\errors\\tests\\test_error.py'}
2025-05-11 13:34:04.461 [INFO] [INFO] No Docker Compose files found for any test files. Continuing without Docker setup.
2025-05-11 13:34:04.463 [ERROR] [ERROR] App caught error:
An error happened in Postgres.connect: Connection refused
Call chain: wrapper
Trace:
c:\Users\Phil\Desktop\Projects\shared-libs\python\errors\tests\test_error.py connect line 62
2025-05-11 13:34:04.464 [INFO] [INFO] Tearing down test environment...
2025-05-11 13:34:03.692 [INFO] [INFO] ++++++++++ Creating EntityUtils
2025-05-11 13:34:03.693 [INFO] [INFO] ++++++++++ EntityUtils custom_serializers: {}
2025-05-11 13:34:03.703 [INFO] [INFO] ++++++++++ Creating EntityUtils
2025-05-11 13:34:03.703 [INFO] [INFO] ++++++++++ EntityUtils custom_serializers: {}
2025-05-11 13:34:03.707 [INFO] [INFO] ++++++++++ Creating EntityUtils
2025-05-11 13:34:03.707 [INFO] [INFO] ++++++++++ EntityUtils custom_serializers: {}
2025-05-11 13:40:08.828 [INFO] [INFO] ++++++++++ Creating EntityUtils
2025-05-11 13:40:08.828 [INFO] [INFO] ++++++++++ EntityUtils custom_serializers: {}
2025-05-11 13:40:08.839 [INFO] [INFO] ++++++++++ Creating EntityUtils
2025-05-11 13:40:08.839 [INFO] [INFO] ++++++++++ EntityUtils custom_serializers: {}
2025-05-11 13:40:08.842 [INFO] [INFO] ++++++++++ Creating EntityUtils
2025-05-11 13:40:08.843 [INFO] [INFO] ++++++++++ EntityUtils custom_serializers: {}
2025-05-11 13:41:42.250 [INFO] [INFO] ++++++++++ Creating EntityUtils
2025-05-11 13:41:42.250 [INFO] [INFO] ++++++++++ EntityUtils custom_serializers: {}
2025-05-11 13:41:42.260 [INFO] [INFO] ++++++++++ Creating EntityUtils
2025-05-11 13:41:42.261 [INFO] [INFO] ++++++++++ EntityUtils custom_serializers: {}
2025-05-11 13:41:42.265 [INFO] [INFO] ++++++++++ Creating EntityUtils
2025-05-11 13:41:42.265 [INFO] [INFO] ++++++++++ EntityUtils custom_serializers: {}
2025-05-11 13:42:18.714 [INFO] [INFO] Setting up test environment...
2025-05-11 13:42:18.714 [INFO] [INFO] Removing .\.pytest_cache
2025-05-11 13:42:18.749 [INFO] [INFO] Test files in this session: {'c:\\Users\\Phil\\Desktop\\Projects\\shared-libs\\python\\errors\\tests\\test_error.py'}
2025-05-11 13:42:18.749 [INFO] [INFO] No Docker Compose files found for any test files. Continuing without Docker setup.
2025-05-11 13:42:18.751 [ERROR] [ERROR] App caught error:
An error happened in Postgres.connect: Connection refused
Trace:
c:\Users\Phil\Desktop\Projects\shared-libs\python\errors\tests\test_error.py connect line 62
2025-05-11 13:42:18.752 [INFO] [INFO] Tearing down test environment...
2025-05-11 14:12:07.809 [INFO] [INFO] ++++++++++ Creating EntityUtils
2025-05-11 14:12:07.809 [INFO] [INFO] ++++++++++ EntityUtils custom_serializers: {}
2025-05-11 14:12:07.818 [INFO] [INFO] ++++++++++ Creating EntityUtils
2025-05-11 14:12:07.818 [INFO] [INFO] ++++++++++ EntityUtils custom_serializers: {}
2025-05-11 14:12:07.822 [INFO] [INFO] ++++++++++ Creating EntityUtils
2025-05-11 14:12:07.822 [INFO] [INFO] ++++++++++ EntityUtils custom_serializers: {}
2025-05-11 14:33:47.766 [INFO] [INFO] ++++++++++ Creating EntityUtils
2025-05-11 14:33:47.766 [INFO] [INFO] ++++++++++ EntityUtils custom_serializers: {}
2025-05-11 14:33:47.774 [INFO] [INFO] ++++++++++ Creating EntityUtils
2025-05-11 14:33:47.774 [INFO] [INFO] ++++++++++ EntityUtils custom_serializers: {}
2025-05-11 14:33:47.779 [INFO] [INFO] ++++++++++ Creating EntityUtils
2025-05-11 14:33:47.779 [INFO] [INFO] ++++++++++ EntityUtils custom_serializers: {}
2025-05-11 14:33:59.811 [INFO] [INFO] Setting up test environment...
2025-05-11 14:33:59.811 [INFO] [INFO] Removing .\.pytest_cache
2025-05-11 14:33:59.849 [INFO] [INFO] Test files in this session: {'c:\\Users\\Phil\\Desktop\\Projects\\shared-libs\\python\\errors\\tests\\test_error.py'}
2025-05-11 14:33:59.850 [INFO] [INFO] No Docker Compose files found for any test files. Continuing without Docker setup.
2025-05-11 14:33:59.993 [INFO] [INFO] Tearing down test environment...
2025-05-11 14:34:54.464 [INFO] [INFO] ++++++++++ Creating EntityUtils
2025-05-11 14:34:54.464 [INFO] [INFO] ++++++++++ EntityUtils custom_serializers: {}
2025-05-11 14:34:54.474 [INFO] [INFO] ++++++++++ Creating EntityUtils
2025-05-11 14:34:54.474 [INFO] [INFO] ++++++++++ EntityUtils custom_serializers: {}
2025-05-11 14:34:54.478 [INFO] [INFO] ++++++++++ Creating EntityUtils
2025-05-11 14:34:54.478 [INFO] [INFO] ++++++++++ EntityUtils custom_serializers: {}
2025-05-11 14:35:01.759 [INFO] [INFO] Setting up test environment...
2025-05-11 14:35:01.760 [INFO] [INFO] Removing .\.pytest_cache
2025-05-11 14:35:01.788 [INFO] [INFO] Test files in this session: {'c:\\Users\\Phil\\Desktop\\Projects\\shared-libs\\python\\errors\\tests\\test_error.py'}
2025-05-11 14:35:01.788 [INFO] [INFO] No Docker Compose files found for any test files. Continuing without Docker setup.
2025-05-11 14:35:01.920 [INFO] [INFO] Tearing down test environment...
2025-05-11 14:35:35.131 [INFO] [INFO] ++++++++++ Creating EntityUtils
2025-05-11 14:35:35.131 [INFO] [INFO] ++++++++++ EntityUtils custom_serializers: {}
2025-05-11 14:35:35.143 [INFO] [INFO] ++++++++++ Creating EntityUtils
2025-05-11 14:35:35.144 [INFO] [INFO] ++++++++++ EntityUtils custom_serializers: {}
2025-05-11 14:35:35.147 [INFO] [INFO] ++++++++++ Creating EntityUtils
2025-05-11 14:35:35.147 [INFO] [INFO] ++++++++++ EntityUtils custom_serializers: {}
2025-05-11 14:35:36.492 [INFO] [INFO] Setting up test environment...
2025-05-11 14:35:36.492 [INFO] [INFO] Removing .\.pytest_cache
2025-05-11 14:35:36.528 [INFO] [INFO] Test files in this session: {'c:\\Users\\Phil\\Desktop\\Projects\\shared-libs\\python\\errors\\tests\\test_error.py'}
2025-05-11 14:35:36.529 [INFO] [INFO] No Docker Compose files found for any test files. Continuing without Docker setup.
2025-05-11 14:35:36.706 [INFO] [INFO] Tearing down test environment...
2025-05-11 14:36:43.447 [INFO] [INFO] ++++++++++ Creating EntityUtils
2025-05-11 14:36:43.447 [INFO] [INFO] ++++++++++ EntityUtils custom_serializers: {}
2025-05-11 14:36:43.458 [INFO] [INFO] ++++++++++ Creating EntityUtils
2025-05-11 14:36:43.458 [INFO] [INFO] ++++++++++ EntityUtils custom_serializers: {}
2025-05-11 14:36:43.463 [INFO] [INFO] ++++++++++ Creating EntityUtils
2025-05-11 14:36:43.463 [INFO] [INFO] ++++++++++ EntityUtils custom_serializers: {}
2025-05-11 14:36:54.363 [INFO] [INFO] ++++++++++ Creating EntityUtils
2025-05-11 14:36:54.363 [INFO] [INFO] ++++++++++ EntityUtils custom_serializers: {}
2025-05-11 14:36:54.373 [INFO] [INFO] ++++++++++ Creating EntityUtils
2025-05-11 14:36:54.374 [INFO] [INFO] ++++++++++ EntityUtils custom_serializers: {}
2025-05-11 14:36:54.378 [INFO] [INFO] ++++++++++ Creating EntityUtils
2025-05-11 14:36:54.379 [INFO] [INFO] ++++++++++ EntityUtils custom_serializers: {}
2025-05-11 14:36:56.761 [INFO] [INFO] Setting up test environment...
2025-05-11 14:36:56.761 [INFO] [INFO] Removing .\.pytest_cache
2025-05-11 14:36:56.805 [INFO] [INFO] Test files in this session: {'c:\\Users\\Phil\\Desktop\\Projects\\shared-libs\\python\\errors\\tests\\test_error.py'}
2025-05-11 14:36:56.806 [INFO] [INFO] No Docker Compose files found for any test files. Continuing without Docker setup.
2025-05-11 14:36:56.809 [ERROR] [ERROR] App caught error:
An error happened in Database.connect: Connection refused
Call chain:  -> Postgres.connect -> Database.connect 
Trace:
c:\Users\Phil\Desktop\Projects\shared-libs\python\errors\tests\test_error.py connect line 62
2025-05-11 14:36:56.810 [INFO] [INFO] Tearing down test environment...
2025-05-11 14:37:48.685 [INFO] [INFO] ++++++++++ Creating EntityUtils
2025-05-11 14:37:48.686 [INFO] [INFO] ++++++++++ EntityUtils custom_serializers: {}
2025-05-11 14:37:48.694 [INFO] [INFO] ++++++++++ Creating EntityUtils
2025-05-11 14:37:48.694 [INFO] [INFO] ++++++++++ EntityUtils custom_serializers: {}
2025-05-11 14:37:48.702 [INFO] [INFO] ++++++++++ Creating EntityUtils
2025-05-11 14:37:48.702 [INFO] [INFO] ++++++++++ EntityUtils custom_serializers: {}
2025-05-11 14:38:06.713 [INFO] [INFO] ++++++++++ Creating EntityUtils
2025-05-11 14:38:06.713 [INFO] [INFO] ++++++++++ EntityUtils custom_serializers: {}
2025-05-11 14:38:06.726 [INFO] [INFO] ++++++++++ Creating EntityUtils
2025-05-11 14:38:06.726 [INFO] [INFO] ++++++++++ EntityUtils custom_serializers: {}
2025-05-11 14:38:06.731 [INFO] [INFO] ++++++++++ Creating EntityUtils
2025-05-11 14:38:06.731 [INFO] [INFO] ++++++++++ EntityUtils custom_serializers: {}
2025-05-11 14:38:08.136 [INFO] [INFO] Setting up test environment...
2025-05-11 14:38:08.136 [INFO] [INFO] Removing .\.pytest_cache
2025-05-11 14:38:08.164 [INFO] [INFO] Test files in this session: {'c:\\Users\\Phil\\Desktop\\Projects\\shared-libs\\python\\errors\\tests\\test_error.py'}
2025-05-11 14:38:08.164 [INFO] [INFO] No Docker Compose files found for any test files. Continuing without Docker setup.
2025-05-11 14:38:08.174 [ERROR] [ERROR] App caught error:
None
Call chain:  -> Postgres.connect -> Database.connect  -> None.wrapper -> None.wrapper  -> None.wrapper -> None.wrapper 
Trace:
c:\Users\Phil\Desktop\Projects\shared-libs\python\errors\try_catch.py wrapper line 74
2025-05-11 14:38:08.175 [INFO] [INFO] Tearing down test environment...
2025-05-11 14:41:15.669 [INFO] [INFO] ++++++++++ Creating EntityUtils
2025-05-11 14:41:15.669 [INFO] [INFO] ++++++++++ EntityUtils custom_serializers: {}
2025-05-11 14:41:15.678 [INFO] [INFO] ++++++++++ Creating EntityUtils
2025-05-11 14:41:15.678 [INFO] [INFO] ++++++++++ EntityUtils custom_serializers: {}
2025-05-11 14:41:15.682 [INFO] [INFO] ++++++++++ Creating EntityUtils
2025-05-11 14:41:15.682 [INFO] [INFO] ++++++++++ EntityUtils custom_serializers: {}
2025-05-11 14:41:20.963 [INFO] [INFO] Setting up test environment...
2025-05-11 14:41:20.964 [INFO] [INFO] Removing .\.pytest_cache
2025-05-11 14:41:20.994 [INFO] [INFO] Test files in this session: {'c:\\Users\\Phil\\Desktop\\Projects\\shared-libs\\python\\errors\\tests\\test_error.py'}
2025-05-11 14:41:20.995 [INFO] [INFO] No Docker Compose files found for any test files. Continuing without Docker setup.
2025-05-11 14:41:21.003 [ERROR] [ERROR] App caught error:
Error in None.wrapper (line 74)
Call chain:  -> Postgres.connect -> Database.connect  -> None.wrapper -> None.wrapper  -> None.wrapper -> None.wrapper 
Trace:
c:\Users\Phil\Desktop\Projects\shared-libs\python\errors\try_catch.py wrapper line 74
2025-05-11 14:41:21.003 [INFO] [INFO] Tearing down test environment...
2025-05-11 14:43:11.617 [INFO] [INFO] ++++++++++ Creating EntityUtils
2025-05-11 14:43:11.617 [INFO] [INFO] ++++++++++ EntityUtils custom_serializers: {}
2025-05-11 14:43:11.627 [INFO] [INFO] ++++++++++ Creating EntityUtils
2025-05-11 14:43:11.627 [INFO] [INFO] ++++++++++ EntityUtils custom_serializers: {}
2025-05-11 14:43:11.631 [INFO] [INFO] ++++++++++ Creating EntityUtils
2025-05-11 14:43:11.632 [INFO] [INFO] ++++++++++ EntityUtils custom_serializers: {}
2025-05-11 14:43:14.509 [INFO] [INFO] Setting up test environment...
2025-05-11 14:43:14.510 [INFO] [INFO] Removing .\.pytest_cache
2025-05-11 14:43:14.541 [INFO] [INFO] Test files in this session: {'c:\\Users\\Phil\\Desktop\\Projects\\shared-libs\\python\\errors\\tests\\test_error.py'}
2025-05-11 14:43:14.542 [INFO] [INFO] No Docker Compose files found for any test files. Continuing without Docker setup.
2025-05-11 14:43:14.544 [ERROR] [ERROR] App caught error:
Error in Database.connect (line 62)
Call chain:  -> Postgres.connect -> Database.connect 
Trace:
c:\Users\Phil\Desktop\Projects\shared-libs\python\errors\tests\test_error.py connect line 62
2025-05-11 14:43:14.545 [INFO] [INFO] Tearing down test environment...
2025-05-11 14:43:41.361 [INFO] [INFO] ++++++++++ Creating EntityUtils
2025-05-11 14:43:41.361 [INFO] [INFO] ++++++++++ EntityUtils custom_serializers: {}
2025-05-11 14:43:41.369 [INFO] [INFO] ++++++++++ Creating EntityUtils
2025-05-11 14:43:41.369 [INFO] [INFO] ++++++++++ EntityUtils custom_serializers: {}
2025-05-11 14:43:41.372 [INFO] [INFO] ++++++++++ Creating EntityUtils
2025-05-11 14:43:41.372 [INFO] [INFO] ++++++++++ EntityUtils custom_serializers: {}
2025-05-11 14:44:06.498 [INFO] [INFO] Setting up test environment...
2025-05-11 14:44:06.498 [INFO] [INFO] Removing .\.pytest_cache
2025-05-11 14:44:06.527 [INFO] [INFO] Test files in this session: {'c:\\Users\\Phil\\Desktop\\Projects\\shared-libs\\python\\errors\\tests\\test_error.py'}
2025-05-11 14:44:06.528 [INFO] [INFO] No Docker Compose files found for any test files. Continuing without Docker setup.
2025-05-11 14:44:06.532 [ERROR] [ERROR] App caught error:
Error in Database.connect (line 62): Connection refused
Call chain:  -> Postgres.connect -> Database.connect 
Trace:
c:\Users\Phil\Desktop\Projects\shared-libs\python\errors\tests\test_error.py connect line 62
2025-05-11 14:44:06.534 [INFO] [INFO] Tearing down test environment...
2025-05-11 14:46:20.969 [INFO] [INFO] ++++++++++ Creating EntityUtils
2025-05-11 14:46:20.969 [INFO] [INFO] ++++++++++ EntityUtils custom_serializers: {}
2025-05-11 14:46:20.976 [INFO] [INFO] ++++++++++ Creating EntityUtils
2025-05-11 14:46:20.977 [INFO] [INFO] ++++++++++ EntityUtils custom_serializers: {}
2025-05-11 14:46:20.980 [INFO] [INFO] ++++++++++ Creating EntityUtils
2025-05-11 14:46:20.980 [INFO] [INFO] ++++++++++ EntityUtils custom_serializers: {}
2025-05-11 14:46:30.742 [INFO] [INFO] Setting up test environment...
2025-05-11 14:46:30.743 [INFO] [INFO] Removing .\.pytest_cache
2025-05-11 14:46:30.774 [INFO] [INFO] Test files in this session: {'c:\\Users\\Phil\\Desktop\\Projects\\shared-libs\\python\\errors\\tests\\test_error.py'}
2025-05-11 14:46:30.775 [INFO] [INFO] No Docker Compose files found for any test files. Continuing without Docker setup.
2025-05-11 14:46:30.904 [INFO] [INFO] Tearing down test environment...
2025-05-11 14:47:27.155 [INFO] [INFO] ++++++++++ Creating EntityUtils
2025-05-11 14:47:27.155 [INFO] [INFO] ++++++++++ EntityUtils custom_serializers: {}
2025-05-11 14:47:27.165 [INFO] [INFO] ++++++++++ Creating EntityUtils
2025-05-11 14:47:27.165 [INFO] [INFO] ++++++++++ EntityUtils custom_serializers: {}
2025-05-11 14:47:27.168 [INFO] [INFO] ++++++++++ Creating EntityUtils
2025-05-11 14:47:27.169 [INFO] [INFO] ++++++++++ EntityUtils custom_serializers: {}
2025-05-11 14:47:34.939 [INFO] [INFO] Setting up test environment...
2025-05-11 14:47:34.940 [INFO] [INFO] Removing .\.pytest_cache
2025-05-11 14:47:34.974 [INFO] [INFO] Test files in this session: {'c:\\Users\\Phil\\Desktop\\Projects\\shared-libs\\python\\errors\\tests\\test_error.py'}
2025-05-11 14:47:34.975 [INFO] [INFO] No Docker Compose files found for any test files. Continuing without Docker setup.
2025-05-11 14:47:34.984 [ERROR] [ERROR] App caught error:
Error in None.wrapper (line 77): Error in None.wrapper (line 77): Error in Database.connect (line 62): Connection refused
Call chain:  -> Postgres.connect -> Database.connect 
Trace:
c:\Users\Phil\Desktop\Projects\shared-libs\python\errors\tests\test_error.py connect line 62
Call chain:  -> Postgres.connect -> Database.connect  -> None.wrapper -> None.wrapper 
Trace:
c:\Users\Phil\Desktop\Projects\shared-libs\python\errors\try_catch.py wrapper line 77
Call chain:  -> Postgres.connect -> Database.connect  -> None.wrapper -> None.wrapper  -> None.wrapper -> None.wrapper 
Trace:
c:\Users\Phil\Desktop\Projects\shared-libs\python\errors\try_catch.py wrapper line 77
2025-05-11 14:47:34.985 [INFO] [INFO] Tearing down test environment...
2025-05-11 15:41:25.303 [INFO] [INFO] ++++++++++ Creating EntityUtils
2025-05-11 15:41:25.303 [INFO] [INFO] ++++++++++ EntityUtils custom_serializers: {}
2025-05-11 15:41:25.312 [INFO] [INFO] ++++++++++ Creating EntityUtils
2025-05-11 15:41:25.312 [INFO] [INFO] ++++++++++ EntityUtils custom_serializers: {}
2025-05-11 15:41:25.316 [INFO] [INFO] ++++++++++ Creating EntityUtils
2025-05-11 15:41:25.316 [INFO] [INFO] ++++++++++ EntityUtils custom_serializers: {}
2025-05-11 15:41:36.977 [INFO] [INFO] ++++++++++ Creating EntityUtils
2025-05-11 15:41:36.977 [INFO] [INFO] ++++++++++ EntityUtils custom_serializers: {}
2025-05-11 15:41:36.989 [INFO] [INFO] ++++++++++ Creating EntityUtils
2025-05-11 15:41:36.989 [INFO] [INFO] ++++++++++ EntityUtils custom_serializers: {}
2025-05-11 15:41:36.993 [INFO] [INFO] ++++++++++ Creating EntityUtils
2025-05-11 15:41:36.993 [INFO] [INFO] ++++++++++ EntityUtils custom_serializers: {}
2025-05-11 15:41:44.886 [INFO] [INFO] Setting up test environment...
2025-05-11 15:41:44.886 [INFO] [INFO] Removing .\.pytest_cache
2025-05-11 15:41:44.917 [INFO] [INFO] Test files in this session: {'c:\\Users\\Phil\\Desktop\\Projects\\shared-libs\\python\\errors\\tests\\test_error.py'}
2025-05-11 15:41:44.918 [INFO] [INFO] No Docker Compose files found for any test files. Continuing without Docker setup.
2025-05-11 15:41:44.920 [ERROR] [ERROR] App caught error:
An error happened in Database.connect: Connection refused
Call chain: Database.connect -> Postgres.reconnect -> do
Trace:
c:\Users\Phil\Desktop\Projects\shared-libs\python\errors\tests\test_error.py connect line 62
2025-05-11 15:41:44.921 [INFO] [INFO] Tearing down test environment...
2025-05-11 15:50:22.376 [INFO] [INFO] ++++++++++ Creating EntityUtils
2025-05-11 15:50:22.376 [INFO] [INFO] ++++++++++ EntityUtils custom_serializers: {}
2025-05-11 15:50:22.386 [INFO] [INFO] ++++++++++ Creating EntityUtils
2025-05-11 15:50:22.386 [INFO] [INFO] ++++++++++ EntityUtils custom_serializers: {}
2025-05-11 15:50:22.390 [INFO] [INFO] ++++++++++ Creating EntityUtils
2025-05-11 15:50:22.390 [INFO] [INFO] ++++++++++ EntityUtils custom_serializers: {}
2025-05-11 15:51:56.731 [INFO] [INFO] ++++++++++ Creating EntityUtils
2025-05-11 15:51:56.731 [INFO] [INFO] ++++++++++ EntityUtils custom_serializers: {}
2025-05-11 15:51:56.741 [INFO] [INFO] ++++++++++ Creating EntityUtils
2025-05-11 15:51:56.741 [INFO] [INFO] ++++++++++ EntityUtils custom_serializers: {}
2025-05-11 15:51:56.748 [INFO] [INFO] ++++++++++ Creating EntityUtils
2025-05-11 15:51:56.748 [INFO] [INFO] ++++++++++ EntityUtils custom_serializers: {}
2025-05-11 15:51:58.827 [INFO] [INFO] Setting up test environment...
2025-05-11 15:51:58.829 [INFO] [INFO] Removing .\.pytest_cache
2025-05-11 15:51:58.889 [INFO] [INFO] Test files in this session: {'c:\\Users\\Phil\\Desktop\\Projects\\shared-libs\\python\\errors\\tests\\test_error.py'}
2025-05-11 15:51:58.890 [INFO] [INFO] No Docker Compose files found for any test files. Continuing without Docker setup.
2025-05-11 15:51:58.894 [ERROR] [ERROR] App caught error:
An error happened in Database.connect: Connection refused
Call chain: <module>
Trace:
c:\Users\Phil\Desktop\Projects\shared-libs\python\errors\tests\test_error.py connect line 62
2025-05-11 15:51:58.895 [INFO] [INFO] Tearing down test environment...
